Workbook

Sheet Mon AM
A1: Date | B1: 4/6 | D1: Shift | E1: AM
B3: Car | C3: Driver | D3: Book | E3: Comm | F3: Radio | G3: NYC CF | H3: PA Fee | I3: CC | J3: DB | K3: Misc | L3: NTD | M3: Cash in/out | N3: Driver Short | O3: Notes
B4: 70 | C4: Alan C | D4: 390 | E4: =IF(AND(VALUE(B4)<100, D4>0),D4*0.5,D4*0.25) -> 195 | F4: =IF(P4="C",Q4,IF(AND(VALUE(B4)<100, D4>0),12,IF(D4>0,2,0))) -> 12 | G4: 0 | H4: 14 | I4: 235.5 | J4: 0 | K4: 0 | L4: =(E4+F4+G4+H4)-I4-J4-K4 -> -14.5 | M4: -14 | N4: -14 | O4: Deducted $14 for 4/7 | R4: Total Book | S4: =D48 -> 7479
B5: 20 | C5: Hammad 125 | D5: 396 | E5: =IF(AND(VALUE(B5)<100, D5>0),D5*0.5,D5*0.25) -> 198 | F5: =IF(P5="C",Q5,IF(AND(VALUE(B5)<100, D5>0),12,IF(D5>0,2,0))) -> 12 | G5: 0 | H5: 10.5 | I5: 328.5 | J5: 28.75 | K5: 0 | L5: =(E5+F5+G5+H5)-I5-J5-K5 -> -136.75 | M5: -137 | N5: -56 | O5: Deducted $56 for 4/8 | R5: Comp Comm | S5: =E48 -> 3382.75
B6: 114 | C6: Ash 114 | D6: 259 | E6: =IF(AND(VALUE(B6)<100, D6>0),D6*0.5,D6*0.25) -> 64.75 | F6: =IF(P6="C",Q6,IF(AND(VALUE(B6)<100, D6>0),12,IF(D6>0,2,0))) -> 2 | G6: 2.75 | H6: 4.25 | I6: 43 | J6: 8.05 | K6: 0 | L6: =(E6+F6+G6+H6)-I6-J6-K6 -> 22.7 | M6: 23 | Q6: 6 | R6: Radio | S6: =F48 -> 240
B7: 326 | C7: Obaydou 326 | D7: 273 | E7: =IF(AND(VALUE(B7)<100, D7>0),D7*0.5,D7*0.25) -> 68.25 | F7: =IF(P7="C",Q7,IF(AND(VALUE(B7)<100, D7>0),12,IF(D7>0,2,0))) -> 2 | G7: 2.75 | H7: 4.25 | I7: 140.46 | J7: 49.45 | K7: 0 | L7: =(E7+F7+G7+H7)-I7-J7-K7 -> -112.66 | M7: -113 | Q7: 6 | R7: NYC CF | S7: =G48 -> 46.75
B8: 33 | C8: Adnan | D8: 264 | E8: =IF(AND(VALUE(B8)<100, D8>0),D8*0.5,D8*0.25) -> 132 | F8: =IF(P8="C",Q8,IF(AND(VALUE(B8)<100, D8>0),12,IF(D8>0,2,0))) -> 12 | G8: 0 | H8: 10.5 | I8: 109 | J8: 40.25 | K8: 0 | L8: =(E8+F8+G8+H8)-I8-J8-K8 -> 5.25 | M8: 5 | Q8: 6 | R8: PA Fee | S8: =H48 -> 168.75
B9: 155 | C9: Abed 155 | E9: =IF(AND(VALUE(B9)<100, D9>0),D9*0.5,D9*0.25) -> 0 | F9: =IF(P9="C",Q9,IF(AND(VALUE(B9)<100, D9>0),12,IF(D9>0,2,0))) -> 0 | L9: =(E9+F9+G9+H9)-I9-J9-K9 -> 0 | Q9: 6 | R9: CC | S9: =I48 -> 3395.58
B10: 80 | C10: Alvis | E10: =IF(AND(VALUE(B10)<100, D10>0),D10*0.5,D10*0.25) -> 0 | F10: =IF(P10="C",Q10,IF(AND(VALUE(B10)<100, D10>0),12,IF(D10>0,2,0))) -> 0 | L10: =(E10+F10+G10+H10)-I10-J10-K10 -> 0 | Q10: 0 | R10: DB | S10: =J48 -> 1138.18
B11: 133 | C11: Bobby 133 | D11: 166 | E11: =IF(AND(VALUE(B11)<100, D11>0),D11*0.5,D11*0.25) -> 41.5 | F11: =IF(P11="C",Q11,IF(AND(VALUE(B11)<100, D11>0),12,IF(D11>0,2,0))) -> 2 | G11: 0 | H11: 0 | I11: 8.05 | J11: 0 | K11: 0 | L11: =(E11+F11+G11+H11)-I11-J11-K11 -> 35.45 | M11: 35 | R11: Misc | S11: =K48 -> 0
B12: 176 | C12: Djilali 176 | D12: 230 | E12: =IF(AND(VALUE(B12)<100, D12>0),D12*0.5,D12*0.25) -> 57.5 | F12: =IF(P12="C",Q12,IF(AND(VALUE(B12)<100, D12>0),12,IF(D12>0,2,0))) -> 2 | G12: 0 | H12: 10.5 | I12: 251.5 | J12: 0 | K12: 0 | L12: =(E12+F12+G12+H12)-I12-J12-K12 -> -181.5 | M12: -181 | Q12: 6 | R12: Driver Short | S12: =N48 -> -83
B13: 122 | C13: Anas 122 | E13: =IF(AND(VALUE(B13)<100, D13>0),D13*0.5,D13*0.25) -> 0 | F13: =IF(P13="C",Q13,IF(AND(VALUE(B13)<100, D13>0),12,IF(D13>0,2,0))) -> 0 | L13: =(E13+F13+G13+H13)-I13-J13-K13 -> 0 | Q13: 6 | S13: =S5+S6+S7-S9-S10-S11-S12 -> -781.26
B14: 88 | C14: Ayad | D14: 256 | E14: =IF(AND(VALUE(B14)<100, D14>0),D14*0.5,D14*0.25) -> 128 | F14: =IF(P14="C",Q14,IF(AND(VALUE(B14)<100, D14>0),12,IF(D14>0,2,0))) -> 12 | G14: 0 | H14: 7 | I14: 85.5 | J14: 139.12 | K14: 0 | L14: =(E14+F14+G14+H14)-I14-J14-K14 -> -77.62 | M14: -78 | Q14: 6 | R14: Cash | S14: =M48 -> -695
B15: 96 | C15: Esmail | D15: 227 | E15: =IF(AND(VALUE(B15)<100, D15>0),D15*0.5,D15*0.25) -> 113.5 | F15: =IF(P15="C",Q15,IF(AND(VALUE(B15)<100, D15>0),12,IF(D15>0,2,0))) -> 12 | G15: 0 | H15: 0 | I15: 30 | J15: 88.55 | K15: 0 | L15: =(E15+F15+G15+H15)-I15-J15-K15 -> 6.95 | M15: 7
B16: 26 | C16: Gus | D16: 297 | E16: =IF(AND(VALUE(B16)<100, D16>0),D16*0.5,D16*0.25) -> 148.5 | F16: =IF(P16="C",Q16,IF(AND(VALUE(B16)<100, D16>0),12,IF(D16>0,2,0))) -> 12 | G16: 11 | H16: 3 | I16: 82.96 | J16: 0 | K16: 0 | L16: =(E16+F16+G16+H16)-I16-J16-K16 -> 91.54 | M16: 92 | Q16: 6
B17: 11 | C17: Hashem | E17: =IF(AND(VALUE(B17)<100, D17>0),D17*0.5,D17*0.25) -> 0 | F17: =IF(P17="C",Q17,IF(AND(VALUE(B17)<100, D17>0),12,IF(D17>0,2,0))) -> 0 | L17: =(E17+F17+G17+H17)-I17-J17-K17 -> 0 | Q17: 6
B18: 27 | C18: Hassan | E18: =IF(AND(VALUE(B18)<100, D18>0),D18*0.5,D18*0.25) -> 0 | F18: =IF(P18="C",Q18,IF(AND(VALUE(B18)<100, D18>0),12,IF(D18>0,2,0))) -> 0 | L18: =(E18+F18+G18+H18)-I18-J18-K18 -> 0 | Q18: 0 | R18: House Cars | S18: {=SUMPRODUCT((VALUE(B4:B47)<100)*(D4:D47>0))} -> 19
B19: 33 | C19: Ihab | E19: =IF(AND(VALUE(B19)<100, D19>0),D19*0.5,D19*0.25) -> 0 | F19: =IF(P19="C",Q19,IF(AND(VALUE(B19)<100, D19>0),12,IF(D19>0,2,0))) -> 0 | L19: =(E19+F19+G19+H19)-I19-J19-K19 -> 0 | Q19: 0 | R19: Private Cars | S19: {=SUMPRODUCT((VALUE(B4:B47)>100)*(D4:D47>0))} -> 6
B20: 77 | C20: Nofal | D20: 239 | E20: =IF(AND(VALUE(B20)<100, D20>0),D20*0.5,D20*0.25) -> 119.5 | F20: =IF(P20="C",Q20,IF(AND(VALUE(B20)<100, D20>0),12,IF(D20>0,2,0))) -> 12 | G20: 2.75 | H20: 7.75 | I20: 8 | J20: 110.46 | K20: 0 | L20: =(E20+F20+G20+H20)-I20-J20-K20 -> 23.54 | M20: 24 | Q20: 0 | R20: Total | S20: =S18+S19 -> 25
B21: 33 | C21: Ibrahim | E21: =IF(AND(VALUE(B21)<100, D21>0),D21*0.5,D21*0.25) -> 0 | F21: =IF(P21="C",Q21,IF(AND(VALUE(B21)<100, D21>0),12,IF(D21>0,2,0))) -> 0 | L21: =(E21+F21+G21+H21)-I21-J21-K21 -> 0 | Q21: 2
B22: 27 | C22: Kim | D22: 232 | E22: =IF(AND(VALUE(B22)<100, D22>0),D22*0.5,D22*0.25) -> 116 | F22: =IF(P22="C",Q22,IF(AND(VALUE(B22)<100, D22>0),12,IF(D22>0,2,0))) -> 12 | G22: 0 | H22: 0 | I22: 48.1 | J22: 23.6 | K22: 0 | L22: =(E22+F22+G22+H22)-I22-J22-K22 -> 56.3 | M22: 56 | Q22: 6
B23: 622 | C23: Joseph 622 | D23: 263 | E23: =IF(AND(VALUE(B23)<100, D23>0),D23*0.5,D23*0.25) -> 65.75 | F23: =IF(P23="C",Q23,IF(AND(VALUE(B23)<100, D23>0),12,IF(D23>0,2,0))) -> 2 | G23: 5.5 | H23: 1.5 | I23: 133.92 | J23: 83.6 | K23: 0 | L23: =(E23+F23+G23+H23)-I23-J23-K23 -> -142.77 | M23: -143 | Q23: 6
B24: 01 | C24: Kamal | D24: 402 | E24: =IF(AND(VALUE(B24)<100, D24>0),D24*0.5,D24*0.25) -> 201 | F24: =IF(P24="C",Q24,IF(AND(VALUE(B24)<100, D24>0),12,IF(D24>0,2,0))) -> 12 | G24: 2.75 | H24: 14.75 | I24: 151.14 | J24: 113.31 | K24: 0 | L24: =(E24+F24+G24+H24)-I24-J24-K24 -> -33.95 | M24: -34
B25: 55 | C25: Karlo | E25: =IF(AND(VALUE(B25)<100, D25>0),D25*0.5,D25*0.25) -> 0 | F25: =IF(P25="C",Q25,IF(AND(VALUE(B25)<100, D25>0),12,IF(D25>0,2,0))) -> 0 | L25: =(E25+F25+G25+H25)-I25-J25-K25 -> 0 | Q25: 0
B26: 77 | C26: Hesham | D26: 321 | E26: =IF(AND(VALUE(B26)<100, D26>0),D26*0.5,D26*0.25) -> 160.5 | F26: =IF(P26="C",Q26,IF(AND(VALUE(B26)<100, D26>0),12,IF(D26>0,2,0))) -> 12 | G26: 2.75 | H26: 14 | I26: 67.21 | J26: 0 | K26: 0 | L26: =(E26+F26+G26+H26)-I26-J26-K26 -> 122.04 | M26: 122 | N26: 0
B27: 77 | C27: Khaled | D27: 519 | E27: =IF(AND(VALUE(B27)<100, D27>0),D27*0.5,D27*0.25) -> 259.5 | F27: =IF(P27="C",Q27,IF(AND(VALUE(B27)<100, D27>0),12,IF(D27>0,2,0))) -> 12 | G27: 8.25 | H27: 12.75 | I27: 111.5 | J27: 96.6 | K27: 0 | L27: =(E27+F27+G27+H27)-I27-J27-K27 -> 84.4 | M27: 84
B28: 844 | C28: Khodr 844 | E28: =IF(AND(VALUE(B28)<100, D28>0),D28*0.5,D28*0.25) -> 0 | F28: =IF(P28="C",Q28,IF(AND(VALUE(B28)<100, D28>0),12,IF(D28>0,2,0))) -> 0 | L28: =(E28+F28+G28+H28)-I28-J28-K28 -> 0
B29: 644 | C29: Muhiddin 644 | D29: 236 | E29: =IF(AND(VALUE(B29)<100, D29>0),D29*0.5,D29*0.25) -> 59 | F29: =IF(P29="C",Q29,IF(AND(VALUE(B29)<100, D29>0),12,IF(D29>0,2,0))) -> 2 | G29: 0 | H29: 10.5 | I29: 187.96 | J29: 0 | K29: 0 | L29: =(E29+F29+G29+H29)-I29-J29-K29 -> -116.46 | M29: -116 | Q29: 6
B30: 109 | C30: Nasser 109 | E30: =IF(AND(VALUE(B30)<100, D30>0),D30*0.5,D30*0.25) -> 0 | F30: =IF(P30="C",Q30,IF(AND(VALUE(B30)<100, D30>0),12,IF(D30>0,2,0))) -> 0 | L30: =(E30+F30+G30+H30)-I30-J30-K30 -> 0 | Q30: 0
B31: 25 | C31: Mustapha | D31: 323 | E31: =IF(AND(VALUE(B31)<100, D31>0),D31*0.5,D31*0.25) -> 161.5 | F31: =IF(P31="C",Q31,IF(AND(VALUE(B31)<100, D31>0),12,IF(D31>0,2,0))) -> 12 | G31: 2.75 | H31: 7.75 | I31: 209.76 | J31: 9.2 | K31: 0 | L31: =(E31+F31+G31+H31)-I31-J31-K31 -> -34.96 | M31: -35
B32: 05 | C32: Nassim | E32: =IF(AND(VALUE(B32)<100, D32>0),D32*0.5,D32*0.25) -> 0 | F32: =IF(P32="C",Q32,IF(AND(VALUE(B32)<100, D32>0),12,IF(D32>0,2,0))) -> 0 | L32: =(E32+F32+G32+H32)-I32-J32-K32 -> 0 | Q32: 6
B33: 02 | C33: Sayed | E33: =IF(AND(VALUE(B33)<100, D33>0),D33*0.5,D33*0.25) -> 0 | F33: =IF(P33="C",Q33,IF(AND(VALUE(B33)<100, D33>0),12,IF(D33>0,2,0))) -> 0 | L33: =(E33+F33+G33+H33)-I33-J33-K33 -> 0
B34: 96 | C34: Rabah | D34: 310 | E34: =IF(AND(VALUE(B34)<100, D34>0),D34*0.5,D34*0.25) -> 155 | F34: =IF(P34="C",Q34,IF(AND(VALUE(B34)<100, D34>0),12,IF(D34>0,2,0))) -> 12 | G34: 2.75 | H34: 7.75 | I34: 161.06 | J34: 0 | K34: 0 | L34: =(E34+F34+G34+H34)-I34-J34-K34 -> 16.44 | M34: 16 | Q34: 5
B35: 33 | C35: Rachid | D35: 417 | E35: =IF(AND(VALUE(B35)<100, D35>0),D35*0.5,D35*0.25) -> 208.5 | F35: =IF(P35="C",Q35,IF(AND(VALUE(B35)<100, D35>0),12,IF(D35>0,2,0))) -> 12 | G35: 2.75 | H35: 0 | I35: 285.72 | J35: 23 | K35: 0 | L35: =(E35+F35+G35+H35)-I35-J35-K35 -> -85.47 | M35: -85 | N35: -8 | O35: Deducted $8 for 4/10 | Q35: 6
B36: 510 | C36: Samuel 510 | E36: =IF(AND(VALUE(B36)<100, D36>0),D36*0.5,D36*0.25) -> 0 | F36: =IF(P36="C",Q36,IF(AND(VALUE(B36)<100, D36>0),12,IF(D36>0,2,0))) -> 0 | L36: =(E36+F36+G36+H36)-I36-J36-K36 -> 0
B37: 132 | C37: Samir 132 | E37: =IF(AND(VALUE(B37)<100, D37>0),D37*0.5,D37*0.25) -> 0 | F37: =IF(P37="C",Q37,IF(AND(VALUE(B37)<100, D37>0),12,IF(D37>0,2,0))) -> 0 | L37: =(E37+F37+G37+H37)-I37-J37-K37 -> 0 | P37: c
B38: 137 | C38: Osama 137 | E38: =IF(AND(VALUE(B38)<100, D38>0),D38*0.5,D38*0.25) -> 0 | F38: =IF(P38="C",Q38,IF(AND(VALUE(B38)<100, D38>0),12,IF(D38>0,2,0))) -> 0 | L38: =(E38+F38+G38+H38)-I38-J38-K38 -> 0 | Q38: 6
B39: 11 | C39: Shalaby | D39: 366 | E39: =IF(AND(VALUE(B39)<100, D39>0),D39*0.5,D39*0.25) -> 183 | F39: =IF(P39="C",Q39,IF(AND(VALUE(B39)<100, D39>0),12,IF(D39>0,2,0))) -> 12 | G39: 0 | H39: 7 | I39: 280.33 | J39: 0 | K39: 0 | L39: =(E39+F39+G39+H39)-I39-J39-K39 -> -78.33 | M39: -78 | Q39: 0
B40: 18 | C40: Spike | D40: 247 | E40: =IF(AND(VALUE(B40)<100, D40>0),D40*0.5,D40*0.25) -> 123.5 | F40: =IF(P40="C",Q40,IF(AND(VALUE(B40)<100, D40>0),12,IF(D40>0,2,0))) -> 12 | G40: 0 | H40: 7 | I40: 226 | J40: 0 | K40: 0 | L40: =(E40+F40+G40+H40)-I40-J40-K40 -> -83.5 | M40: -83 | N40: -1 | O40: Deducted $1 for 4/10
B41: 169 | C41: Tariq 169 | E41: =IF(AND(VALUE(B41)<100, D41>0),D41*0.5,D41*0.25) -> 0 | F41: =IF(P41="C",Q41,IF(AND(VALUE(B41)<100, D41>0),12,IF(D41>0,2,0))) -> 0 | L41: =(E41+F41+G41+H41)-I41-J41-K41 -> 0
...

Sheet Mon PM
A1: Date | B1: ='Mon AM'!B1 -> 4/6 | D1: Shift | E1: PM
B3: Car | C3: Driver | D3: Book | E3: Comm | F3: Radio | G3: NYC CF | H3: PA Fee | I3: CC | J3: DB | K3: Misc | L3: NTD | M3: Cash in/out | N3: Driver Short | O3: Notes
B4: 138 | C4: Akram 138 | E4: =IF(AND(VALUE(B4)<100, D4>0),D4*0.5,D4*0.25) -> 0 | F4: =IF(P4="C",Q4,IF(AND(VALUE(B4)<100, D4>0),12,IF(D4>0,2,0))) -> 0 | L4: =(E4+F4+G4+H4)-I4-J4-K4 -> 0 | P4: c | Q4: 0 | R4: Total Book | S4: =D48 -> 2789
B5: 277 | C5: Nasser 277 | D5: 92 | E5: =IF(AND(VALUE(B5)<100, D5>0),D5*0.5,D5*0.25) -> 23 | F5: =IF(P5="C",Q5,IF(AND(VALUE(B5)<100, D5>0),12,IF(D5>0,2,0))) -> 2 | G5: 0 | H5: 0 | I5: 0 | J5: 0 | K5: 0 | L5: =(E5+F5+G5+H5)-I5-J5-K5 -> 25 | M5: 1 | N5: 24 | Q5: 6 | R5: Comp Comm | S5: =E48 -> 1304
B6: 667 | C6: Abid 667 | E6: =IF(AND(VALUE(B6)<100, D6>0),D6*0.5,D6*0.25) -> 0 | F6: =IF(P6="C",Q6,IF(AND(VALUE(B6)<100, D6>0),12,IF(D6>0,2,0))) -> 0 | L6: =(E6+F6+G6+H6)-I6-J6-K6 -> 0 | Q6: 0 | R6: Radio | S6: =F48 -> 96
B7: 70 | C7: Alhassan | D7: 443 | E7: =IF(AND(VALUE(B7)<100, D7>0),D7*0.5,D7*0.25) -> 221.5 | F7: =IF(P7="C",Q7,IF(AND(VALUE(B7)<100, D7>0),12,IF(D7>0,2,0))) -> 12 | G7: 0 | H7: 17.5 | I7: 218 | J7: 0 | K7: 0 | L7: =(E7+F7+G7+H7)-I7-J7-K7 -> 33 | M7: 33 | Q7: 6 | R7: NYC CF | S7: =G48 -> 13.75
B8: 210 | C8: Boumadian | E8: =IF(AND(VALUE(B8)<100, D8>0),D8*0.5,D8*0.25) -> 0 | F8: =IF(P8="C",Q8,IF(AND(VALUE(B8)<100, D8>0),12,IF(D8>0,2,0))) -> 0 | L8: =(E8+F8+G8+H8)-I8-J8-K8 -> 0 | Q8: 6 | R8: PA Fee | S8: =H48 -> 72.25
B9: 012 | C9: Hamed | D9: 372 | E9: =IF(AND(VALUE(B9)<100, D9>0),D9*0.5,D9*0.25) -> 186 | F9: =IF(P9="C",Q9,IF(AND(VALUE(B9)<100, D9>0),12,IF(D9>0,2,0))) -> 12 | G9: 0 | H9: 10.5 | I9: 63.5 | J9: 115 | K9: 0 | L9: =(E9+F9+G9+H9)-I9-J9-K9 -> 30 | M9: 30 | Q9: 0 | R9: CC | S9: =I48 -> 1037.39
B10: 44 | C10: Cono | E10: =IF(AND(VALUE(B10)<100, D10>0),D10*0.5,D10*0.25) -> 0 | F10: =IF(P10="C",Q10,IF(AND(VALUE(B10)<100, D10>0),12,IF(D10>0,2,0))) -> 0 | L10: =(E10+F10+G10+H10)-I10-J10-K10 -> 0 | Q10: 6 | R10: DB | S10: =J48 -> 559.21
B11: 15 | C11: Hamdy | D11: 142 | E11: =IF(AND(VALUE(B11)<100, D11>0),D11*0.5,D11*0.25) -> 71 | F11: =IF(P11="C",Q11,IF(AND(VALUE(B11)<100, D11>0),12,IF(D11>0,2,0))) -> 6 | G11: 0 | H11: 0 | I11: 23.7 | J11: 33.95 | K11: 0 | L11: =(E11+F11+G11+H11)-I11-J11-K11 -> 19.35 | M11: 19 | N11: 0 | P11: c | Q11: 6 | R11: Misc | S11: =K48 -> 0
B12: 44 | C12: Divakar | D12: 290 | E12: =IF(AND(VALUE(B12)<100, D12>0),D12*0.5,D12*0.25) -> 145 | F12: =IF(P12="C",Q12,IF(AND(VALUE(B12)<100, D12>0),12,IF(D12>0,2,0))) -> 12 | G12: 0 | H12: 3.5 | I12: 0 | J12: 29.9 | K12: 0 | L12: =(E12+F12+G12+H12)-I12-J12-K12 -> 130.6 | M12: 131 | Q12: 6 | R12: Driver Short | S12: =N48 -> 1
B13: 012 | C13: Hosari | E13: =IF(AND(VALUE(B13)<100, D13>0),D13*0.5,D13*0.25) -> 0 | F13: =IF(P13="C",Q13,IF(AND(VALUE(B13)<100, D13>0),12,IF(D13>0,2,0))) -> 0 | L13: =(E13+F13+G13+H13)-I13-J13-K13 -> 0 | S13: =S5+S6+S7-S9-S10-S11-S12 -> -183.85
B14: 44 | C14: Ihab | E14: =IF(AND(VALUE(B14)<100, D14>0),D14*0.5,D14*0.25) -> 0 | F14: =IF(P14="C",Q14,IF(AND(VALUE(B14)<100, D14>0),12,IF(D14>0,2,0))) -> 0 | L14: =(E14+F14+G14+H14)-I14-J14-K14 -> 0 | R14: Cash | S14: =M48 -> -134
B15: 345 | C15: Abood 345 | E15: =IF(AND(VALUE(B15)<100, D15>0),D15*0.5,D15*0.25) -> 0 | F15: =IF(P15="C",Q15,IF(AND(VALUE(B15)<100, D15>0),12,IF(D15>0,2,0))) -> 0 | L15: =(E15+F15+G15+H15)-I15-J15-K15 -> 0
B16: 11 | C16: Johnny 120 | E16: =IF(AND(VALUE(B16)<100, D16>0),D16*0.5,D16*0.25) -> 0 | F16: =IF(P16="C",Q16,IF(AND(VALUE(B16)<100, D16>0),12,IF(D16>0,2,0))) -> 0 | L16: =(E16+F16+G16+H16)-I16-J16-K16 -> 0 | P16: c
B17: 02 | C17: Kuhali | E17: =IF(AND(VALUE(B17)<100, D17>0),D17*0.5,D17*0.25) -> 0 | F17: =IF(P17="C",Q17,IF(AND(VALUE(B17)<100, D17>0),12,IF(D17>0,2,0))) -> 0 | L17: =(E17+F17+G17+H17)-I17-J17-K17 -> 0
B18: 95 | C18: Maroc | E18: =IF(AND(VALUE(B18)<100, D18>0),D18*0.5,D18*0.25) -> 0 | F18: =IF(P18="C",Q18,IF(AND(VALUE(B18)<100, D18>0),12,IF(D18>0,2,0))) -> 0 | L18: =(E18+F18+G18+H18)-I18-J18-K18 -> 0 | R18: House Cars | S18: {=SUMPRODUCT((VALUE(B4:B47)<100)*(D4:D47>0))} -> 8
B19: 18 | C19: Mourad | E19: =IF(AND(VALUE(B19)<100, D19>0),D19*0.5,D19*0.25) -> 0 | F19: =IF(P19="C",Q19,IF(AND(VALUE(B19)<100, D19>0),12,IF(D19>0,2,0))) -> 0 | L19: =(E19+F19+G19+H19)-I19-J19-K19 -> 0 | R19: Private Cars | S19: {=SUMPRODUCT((VALUE(B4:B47)>100)*(D4:D47>0))} -> 3
B20: 06 | C20: Peter | D20: 262 | E20: =IF(AND(VALUE(B20)<100, D20>0),D20*0.5,D20*0.25) -> 131 | F20: =IF(P20="C",Q20,IF(AND(VALUE(B20)<100, D20>0),12,IF(D20>0,2,0))) -> 12 | G20: 0 | H20: 7 | I20: 242.32 | J20: 0 | K20: 0 | L20: =(E20+F20+G20+H20)-I20-J20-K20 -> -92.32 | M20: -92 | R20: Total | S20: =S18+S19 -> 11
B21: 44 | C21: Madjid | E21: =IF(AND(VALUE(B21)<100, D21>0),D21*0.5,D21*0.25) -> 0 | F21: =IF(P21="C",Q21,IF(AND(VALUE(B21)<100, D21>0),12,IF(D21>0,2,0))) -> 0 | L21: =(E21+F21+G21+H21)-I21-J21-K21 -> 0
B22: 01 | C22: Smail | D22: 308 | E22: =IF(AND(VALUE(B22)<100, D22>0),D22*0.5,D22*0.25) -> 154 | F22: =IF(P22="C",Q22,IF(AND(VALUE(B22)<100, D22>0),12,IF(D22>0,2,0))) -> 12 | G22: 0 | H22: 10.5 | I22: 114.5 | J22: 83.92 | K22: 0 | L22: =(E22+F22+G22+H22)-I22-J22-K22 -> -21.92 | M22: -22 | N22: -22 | O22: Deducted $22 for 4/10 & 4/9 | Q22: 6
B23: 05 | C23: Soufiane | E23: =IF(AND(VALUE(B23)<100, D23>0),D23*0.5,D23*0.25) -> 0 | F23: =IF(P23="C",Q23,IF(AND(VALUE(B23)<100, D23>0),12,IF(D23>0,2,0))) -> 0 | L23: =(E23+F23+G23+H23)-I23-J23-K23 -> 0 | P23: c | Q23: 0
B24: 012 | C24: Reda | E24: =IF(AND(VALUE(B24)<100, D24>0),D24*0.5,D24*0.25) -> 0 | F24: =IF(P24="C",Q24,IF(AND(VALUE(B24)<100, D24>0),12,IF(D24>0,2,0))) -> 0 | L24: =(E24+F24+G24+H24)-I24-J24-K24 -> 0 | P24: c | Q24: 0
B25: 33 | C25: Zaki | D25: 308 | E25: =IF(AND(VALUE(B25)<100, D25>0),D25*0.5,D25*0.25) -> 154 | F25: =IF(P25="C",Q25,IF(AND(VALUE(B25)<100, D25>0),12,IF(D25>0,2,0))) -> 12 | G25: 8.25 | H25: 0.75 | I25: 67.96 | J25: 223.38 | K25: 0 | L25: =(E25+F25+G25+H25)-I25-J25-K25 -> -116.34 | M25: -116
B26: 662 | C26: Aly 662 | D26: 126 | E26: =IF(AND(VALUE(B26)<100, D26>0),D26*0.5,D26*0.25) -> 31.5 | F26: =IF(P26="C",Q26,IF(AND(VALUE(B26)<100, D26>0),12,IF(D26>0,2,0))) -> 2 | G26: 0 | H26: 3.5 | I26: 84.95 | J26: 0 | K26: 0 | L26: =(E26+F26+G26+H26)-I26-J26-K26 -> -47.95 | M26: -48 | N26: -1 | O26: Deducted $1 for 4/9
B27: 02 | C27: Hassan | E27: =IF(AND(VALUE(B27)<100, D27>0),D27*0.5,D27*0.25) -> 0 | F27: =IF(P27="C",Q27,IF(AND(VALUE(B27)<100, D27>0),12,IF(D27>0,2,0))) -> 0 | L27: =(E27+F27+G27+H27)-I27-J27-K27 -> 0
B28: 445 | C28: Sadiki 445 | E28: =IF(AND(VALUE(B28)<100, D28>0),D28*0.5,D28*0.25) -> 0 | F28: =IF(P28="C",Q28,IF(AND(VALUE(B28)<100, D28>0),12,IF(D28>0,2,0))) -> 0 | L28: =(E28+F28+G28+H28)-I28-J28-K28 -> 0
B29: 7 | C29: Rushdi | E29: =IF(AND(VALUE(B29)<100, D29>0),D29*0.5,D29*0.25) -> 0 | F29: =IF(P29="C",Q29,IF(AND(VALUE(B29)<100, D29>0),12,IF(D29>0,2,0))) -> 0 | L29: =(E29+F29+G29+H29)-I29-J29-K29 -> 0
B30: 77 | C30: Shousha | E30: =IF(AND(VALUE(B30)<100, D30>0),D30*0.5,D30*0.25) -> 0 | F30: =IF(P30="C",Q30,IF(AND(VALUE(B30)<100, D30>0),12,IF(D30>0,2,0))) -> 0 | L30: =(E30+F30+G30+H30)-I30-J30-K30 -> 0
B31: 610 | C31: Rizwan 610 | E31: =IF(AND(VALUE(B31)<100, D31>0),D31*0.5,D31*0.25) -> 0 | F31: =IF(P31="C",Q31,IF(AND(VALUE(B31)<100, D31>0),12,IF(D31>0,2,0))) -> 0 | L31: =(E31+F31+G31+H31)-I31-J31-K31 -> 0
B32: 05 | C32: Sayah | D32: 302 | E32: =IF(AND(VALUE(B32)<100, D32>0),D32*0.5,D32*0.25) -> 151 | F32: =IF(P32="C",Q32,IF(AND(VALUE(B32)<100, D32>0),12,IF(D32>0,2,0))) -> 12 | G32: 2.75 | H32: 14.75 | I32: 124.5 | J32: 73.06 | K32: 0 | L32: =(E32+F32+G32+H32)-I32-J32-K32 -> -17.06 | M32: -17
B33: 101 | C33: Helal 101 | E33: =IF(AND(VALUE(B33)<100, D33>0),D33*0.5,D33*0.25) -> 0 | F33: =IF(P33="C",Q33,IF(AND(VALUE(B33)<100, D33>0),12,IF(D33>0,2,0))) -> 0 | L33: =(E33+F33+G33+H33)-I33-J33-K33 -> 0
B34: 434 | C34: Radwan 434 | D34: 144 | E34: =IF(AND(VALUE(B34)<100, D34>0),D34*0.5,D34*0.25) -> 36 | F34: =IF(P34="C",Q34,IF(AND(VALUE(B34)<100, D34>0),12,IF(D34>0,2,0))) -> 2 | G34: 2.75 | H34: 4.25 | I34: 97.96 | J34: 0 | K34: 0 | L34: =(E34+F34+G34+H34)-I34-J34-K34 -> -52.96 | M34: -53
B35: 109 | C35: Nasser 109 | E35: =IF(AND(VALUE(B35)<100, D35>0),D35*0.5,D35*0.25) -> 0 | F35: =IF(P35="C",Q35,IF(AND(VALUE(B35)<100, D35>0),12,IF(D35>0,2,0))) -> 0 | L35: =(E35+F35+G35+H35)-I35-J35-K35 -> 0
B36: 326 | C36: Obaydou 326 | E36: =IF(AND(VALUE(B36)<100, D36>0),D36*0.5,D36*0.25) -> 0 | F36: =IF(P36="C",Q36,IF(AND(VALUE(B36)<100, D36>0),12,IF(D36>0,2,0))) -> 0 | L36: =(E36+F36+G36+H36)-I36-J36-K36 -> 0
E37: =IF(AND(VALUE(B37)<100, D37>0),D37*0.5,D37*0.25) -> 0 | F37: =IF(P37="C",Q37,IF(AND(VALUE(B37)<100, D37>0),12,IF(D37>0,2,0))) -> 0 | L37: =(E37+F37+G37+H37)-I37-J37-K37 -> 0
E38: =IF(AND(VALUE(B38)<100, D38>0),D38*0.5,D38*0.25) -> 0 | F38: =IF(P38="C",Q38,IF(AND(VALUE(B38)<100, D38>0),12,IF(D38>0,2,0))) -> 0 | L38: =(E38+F38+G38+H38)-I38-J38-K38 -> 0
E39: =IF(AND(VALUE(B39)<100, D39>0),D39*0.5,D39*0.25) -> 0 | F39: =IF(P39="C",Q39,IF(AND(VALUE(B39)<100, D39>0),12,IF(D39>0,2,0))) -> 0 | L39: =(E39+F39+G39+H39)-I39-J39-K39 -> 0
E40: =IF(AND(VALUE(B40)<100, D40>0),D40*0.5,D40*0.25) -> 0 | F40: =IF(P40="C",Q40,IF(AND(VALUE(B40)<100, D40>0),12,IF(D40>0,2,0))) -> 0 | L40: =(E40+F40+G40+H40)-I40-J40-K40 -> 0
E41: =IF(AND(VALUE(B41)<100, D41>0),D41*0.5,D41*0.25) -> 0 | F41: =IF(P41="C",Q41,IF(AND(VALUE(B41)<100, D41>0),12,IF(D41>0,2,0))) -> 0 | L41: =(E41+F41+G41+H41)-I41-J41-K41 -> 0
...

Sheet Tues AM
A1: Date | B1: ='Mon AM'!B1+1 -> 46119 | D1: Shift | E1: AM
B3: Car | C3: Driver | D3: Book | E3: Comm | F3: Radio | G3: NYC CF | H3: PA Fee | I3: CC | J3: DB | K3: Misc | L3: NTD | M3: Cash in/out | N3: Driver Short | O3: Notes
B4: 70 | C4: Alan C | D4: 240 | E4: =IF(AND(VALUE(B4)<100, D4>0),D4*0.5,D4*0.25) -> 120 | F4: =IF(P4="C",Q4,IF(AND(VALUE(B4)<100, D4>0),12,IF(D4>0,2,0))) -> 12 | G4: 0 | H4: 7 | I4: 58.5 | J4: 46 | K4: 0 | L4: =(E4+F4+G4+H4)-I4-J4-K4 -> 34.5 | M4: 34 | N4: 0 | Q4: 6 | R4: Total Book | S4: =D48 -> 7097.94
B5: 20 | C5: Hammad 125 | D5: 391.94 | E5: =IF(AND(VALUE(B5)<100, D5>0),D5*0.5,D5*0.25) -> 195.97 | F5: =IF(P5="C",Q5,IF(AND(VALUE(B5)<100, D5>0),12,IF(D5>0,2,0))) -> 12 | G5: 5.5 | H5: 7 | I5: 68.5 | J5: 226.34 | K5: 0 | L5: =(E5+F5+G5+H5)-I5-J5-K5 -> -74.37 | M5: -74 | Q5: 0 | R5: Comp Comm | S5: =E48 -> 3210.72
B6: 114 | C6: Ash 114 | D6: 210 | E6: =IF(AND(VALUE(B6)<100, D6>0),D6*0.5,D6*0.25) -> 52.5 | F6: =IF(P6="C",Q6,IF(AND(VALUE(B6)<100, D6>0),12,IF(D6>0,2,0))) -> 2 | G6: 0 | H6: 3.5 | I6: 60.5 | J6: 20 | K6: 0 | L6: =(E6+F6+G6+H6)-I6-J6-K6 -> -22.5 | M6: -22 | Q6: 6 | R6: Radio | S6: =F48 -> 254
B7: 326 | C7: Obaydou 326 | D7: 215 | E7: =IF(AND(VALUE(B7)<100, D7>0),D7*0.5,D7*0.25) -> 53.75 | F7: =IF(P7="C",Q7,IF(AND(VALUE(B7)<100, D7>0),12,IF(D7>0,2,0))) -> 2 | G7: 0 | H7: 7 | I7: 142 | J7: 7 | K7: 0 | L7: =(E7+F7+G7+H7)-I7-J7-K7 -> -86.25 | M7: -86 | Q7: 6 | R7: NYC CF | S7: =G48 -> 71.5
B8: 33 | C8: Adnan | D8: 291 | E8: =IF(AND(VALUE(B8)<100, D8>0),D8*0.5,D8*0.25) -> 145.5 | F8: =IF(P8="C",Q8,IF(AND(VALUE(B8)<100, D8>0),12,IF(D8>0,2,0))) -> 12 | G8: 0 | H8: 3.5 | I8: 157.5 | J8: 41.4 | K8: 0 | L8: =(E8+F8+G8+H8)-I8-J8-K8 -> -37.9 | M8: -38 | Q8: 6 | R8: PA Fee | S8: =H48 -> 124.25
B9: 155 | C9: Abed 155 | E9: =IF(AND(VALUE(B9)<100, D9>0),D9*0.5,D9*0.25) -> 0 | F9: =IF(P9="C",Q9,IF(AND(VALUE(B9)<100, D9>0),12,IF(D9>0,2,0))) -> 0 | L9: =(E9+F9+G9+H9)-I9-J9-K9 -> 0 | Q9: 6 | R9: CC | S9: =I48 -> 2384.24
B10: 44 | C10: Alvis | D10: 193 | E10: =IF(AND(VALUE(B10)<100, D10>0),D10*0.5,D10*0.25) -> 96.5 | F10: =IF(P10="C",Q10,IF(AND(VALUE(B10)<100, D10>0),12,IF(D10>0,2,0))) -> 12 | G10: 2.75 | H10: 0 | I10: 24.6 | J10: 76.21 | K10: 0 | L10: =(E10+F10+G10+H10)-I10-J10-K10 -> 10.44 | M10: 10 | N10: 0 | R10: DB | S10: =J48 -> 1122.09
B11: 133 | C11: Bobby 133 | D11: 158 | E11: =IF(AND(VALUE(B11)<100, D11>0),D11*0.5,D11*0.25) -> 39.5 | F11: =IF(P11="C",Q11,IF(AND(VALUE(B11)<100, D11>0),12,IF(D11>0,2,0))) -> 2 | G11: 0 | H11: 0 | I11: 57 | J11: 0 | K11: 0 | L11: =(E11+F11+G11+H11)-I11-J11-K11 -> -15.5 | M11: -15 | N11: -13 | O11: Deducted $13 for 4/9 | R11: Misc | S11: =K48 -> 17
B12: 176 | C12: Djilali 176 | D12: 254 | E12: =IF(AND(VALUE(B12)<100, D12>0),D12*0.5,D12*0.25) -> 63.5 | F12: =IF(P12="C",Q12,IF(AND(VALUE(B12)<100, D12>0),12,IF(D12>0,2,0))) -> 2 | G12: 5.5 | H12: 8.5 | I12: 129.46 | J12: 63.86 | K12: 0 | L12: =(E12+F12+G12+H12)-I12-J12-K12 -> -113.82 | M12: -114 | Q12: 0 | R12: Driver Short | S12: =N48 -> -20
B13: 122 | C13: Anas 122 | E13: =IF(AND(VALUE(B13)<100, D13>0),D13*0.5,D13*0.25) -> 0 | F13: =IF(P13="C",Q13,IF(AND(VALUE(B13)<100, D13>0),12,IF(D13>0,2,0))) -> 0 | L13: =(E13+F13+G13+H13)-I13-J13-K13 -> 0 | Q13: 6 | S13: =S5+S6+S7-S9-S10-S11-S12 -> 32.89
B14: 88 | C14: Ayad | E14: =IF(AND(VALUE(B14)<100, D14>0),D14*0.5,D14*0.25) -> 0 | F14: =IF(P14="C",Q14,IF(AND(VALUE(B14)<100, D14>0),12,IF(D14>0,2,0))) -> 0 | L14: =(E14+F14+G14+H14)-I14-J14-K14 -> 0 | Q14: 0 | R14: Cash | S14: =M48 -> 136
B15: 96 | C15: Esmail | D15: 320 | E15: =IF(AND(VALUE(B15)<100, D15>0),D15*0.5,D15*0.25) -> 160 | F15: =IF(P15="C",Q15,IF(AND(VALUE(B15)<100, D15>0),12,IF(D15>0,2,0))) -> 12 | G15: 0 | H15: 7 | I15: 94.5 | J15: 0 | K15: 0 | L15: =(E15+F15+G15+H15)-I15-J15-K15 -> 84.5 | M15: 84 | N15: 0
B16: 26 | C16: Gus | D16: 267 | E16: =IF(AND(VALUE(B16)<100, D16>0),D16*0.5,D16*0.25) -> 133.5 | F16: =IF(P16="C",Q16,IF(AND(VALUE(B16)<100, D16>0),12,IF(D16>0,2,0))) -> 12 | G16: 5.5 | H16: 5 | I16: 7 | J16: 43.4 | K16: 0 | L16: =(E16+F16+G16+H16)-I16-J16-K16 -> 105.6 | M16: 106 | Q16: 0
B17: 11 | C17: Hashem | E17: =IF(AND(VALUE(B17)<100, D17>0),D17*0.5,D17*0.25) -> 0 | F17: =IF(P17="C",Q17,IF(AND(VALUE(B17)<100, D17>0),12,IF(D17>0,2,0))) -> 0 | L17: =(E17+F17+G17+H17)-I17-J17-K17 -> 0 | Q17: 6
B18: 27 | C18: Hassan | E18: =IF(AND(VALUE(B18)<100, D18>0),D18*0.5,D18*0.25) -> 0 | F18: =IF(P18="C",Q18,IF(AND(VALUE(B18)<100, D18>0),12,IF(D18>0,2,0))) -> 0 | L18: =(E18+F18+G18+H18)-I18-J18-K18 -> 0 | Q18: 0 | R18: House Cars | S18: {=SUMPRODUCT((VALUE(B4:B47)<100)*(D4:D47>0))} -> 20
B19: 33 | C19: Ihab | E19: =IF(AND(VALUE(B19)<100, D19>0),D19*0.5,D19*0.25) -> 0 | F19: =IF(P19="C",Q19,IF(AND(VALUE(B19)<100, D19>0),12,IF(D19>0,2,0))) -> 0 | L19: =(E19+F19+G19+H19)-I19-J19-K19 -> 0 | Q19: 6 | R19: Private Cars | S19: {=SUMPRODUCT((VALUE(B4:B47)>100)*(D4:D47>0))} -> 7
B20: 77 | C20: Nofal | D20: 285 | E20: =IF(AND(VALUE(B20)<100, D20>0),D20*0.5,D20*0.25) -> 142.5 | F20: =IF(P20="C",Q20,IF(AND(VALUE(B20)<100, D20>0),12,IF(D20>0,2,0))) -> 12 | G20: 2.75 | H20: 4.25 | I20: 101.1 | J20: 0 | K20: 0 | L20: =(E20+F20+G20+H20)-I20-J20-K20 -> 60.4 | M20: 60 | Q20: 6 | R20: Total | S20: =S18+S19 -> 27
B21: 33 | C21: Ibrahim | E21: =IF(AND(VALUE(B21)<100, D21>0),D21*0.5,D21*0.25) -> 0 | F21: =IF(P21="C",Q21,IF(AND(VALUE(B21)<100, D21>0),12,IF(D21>0,2,0))) -> 0 | L21: =(E21+F21+G21+H21)-I21-J21-K21 -> 0 | Q21: 2
B22: 27 | C22: Kim | D22: 200 | E22: =IF(AND(VALUE(B22)<100, D22>0),D22*0.5,D22*0.25) -> 100 | F22: =IF(P22="C",Q22,IF(AND(VALUE(B22)<100, D22>0),12,IF(D22>0,2,0))) -> 12 | G22: 0 | H22: 0 | I22: 8 | J22: 28.75 | K22: 0 | L22: =(E22+F22+G22+H22)-I22-J22-K22 -> 75.25 | M22: 75 | Q22: 6
B23: 622 | C23: Joseph 622 | D23: 128 | E23: =IF(AND(VALUE(B23)<100, D23>0),D23*0.5,D23*0.25) -> 32 | F23: =IF(P23="C",Q23,IF(AND(VALUE(B23)<100, D23>0),12,IF(D23>0,2,0))) -> 2 | G23: 0 | H23: 0 | I23: 8.05 | J23: 28.75 | K23: 0 | L23: =(E23+F23+G23+H23)-I23-J23-K23 -> -2.8 | M23: -3 | Q23: 6
B24: 01 | C24: Kamal | D24: 407 | E24: =IF(AND(VALUE(B24)<100, D24>0),D24*0.5,D24*0.25) -> 203.5 | F24: =IF(P24="C",Q24,IF(AND(VALUE(B24)<100, D24>0),12,IF(D24>0,2,0))) -> 12 | G24: 5.5 | H24: 12 | I24: 106.55 | J24: 0 | K24: 0 | L24: =(E24+F24+G24+H24)-I24-J24-K24 -> 126.45 | M24: 126
B25: 55 | C25: Karlo | D25: 296 | E25: =IF(AND(VALUE(B25)<100, D25>0),D25*0.5,D25*0.25) -> 148 | F25: =IF(P25="C",Q25,IF(AND(VALUE(B25)<100, D25>0),12,IF(D25>0,2,0))) -> 12 | G25: 5.5 | H25: 1.5 | I25: 61.56 | J25: 51.75 | K25: 0 | L25: =(E25+F25+G25+H25)-I25-J25-K25 -> 53.69 | M25: 54 | Q25: 0
B26: 77 | C26: Hesham | D26: 222 | E26: =IF(AND(VALUE(B26)<100, D26>0),D26*0.5,D26*0.25) -> 111 | F26: =IF(P26="C",Q26,IF(AND(VALUE(B26)<100, D26>0),12,IF(D26>0,2,0))) -> 12 | G26: 2.75 | H26: 7.75 | I26: 134.96 | J26: 10.35 | K26: 0 | L26: =(E26+F26+G26+H26)-I26-J26-K26 -> -11.81 | M26: -12 | N26: -7 | O26: Deducted $7 for 4/6
B27: 77 | C27: Khaled | D27: 312 | E27: =IF(AND(VALUE(B27)<100, D27>0),D27*0.5,D27*0.25) -> 156 | F27: =IF(P27="C",Q27,IF(AND(VALUE(B27)<100, D27>0),12,IF(D27>0,2,0))) -> 12 | G27: 5.5 | H27: 1.5 | I27: 98.96 | J27: 149.47 | K27: 0 | L27: =(E27+F27+G27+H27)-I27-J27-K27 -> -73.43 | M27: -73 | Q27: 0 | T27: 5
B28: 844 | C28: Khodr 844 | E28: =IF(AND(VALUE(B28)<100, D28>0),D28*0.5,D28*0.25) -> 0 | F28: =IF(P28="C",Q28,IF(AND(VALUE(B28)<100, D28>0),12,IF(D28>0,2,0))) -> 0 | L28: =(E28+F28+G28+H28)-I28-J28-K28 -> 0 | Q28: 6 | T28: 4
B29: 644 | C29: Muhiddin 644 | D29: 229 | E29: =IF(AND(VALUE(B29)<100, D29>0),D29*0.5,D29*0.25) -> 57.25 | F29: =IF(P29="C",Q29,IF(AND(VALUE(B29)<100, D29>0),12,IF(D29>0,2,0))) -> 2 | G29: 0 | H29: 10.5 | I29: 8.4 | J29: 61 | K29: 0 | L29: =(E29+F29+G29+H29)-I29-J29-K29 -> 0.35 | M29: 0 | Q29: 6
B30: 109 | C30: Nasser 109 | E30: =IF(AND(VALUE(B30)<100, D30>0),D30*0.5,D30*0.25) -> 0 | F30: =IF(P30="C",Q30,IF(AND(VALUE(B30)<100, D30>0),12,IF(D30>0,2,0))) -> 0 | L30: =(E30+F30+G30+H30)-I30-J30-K30 -> 0 | Q30: 6
B31: 25 | C31: Mustapha | D31: 283 | E31: =IF(AND(VALUE(B31)<100, D31>0),D31*0.5,D31*0.25) -> 141.5 | F31: =IF(P31="C",Q31,IF(AND(VALUE(B31)<100, D31>0),12,IF(D31>0,2,0))) -> 12 | G31: 5.5 | H31: 5 | I31: 86.92 | J31: 63.86 | K31: 0 | L31: =(E31+F31+G31+H31)-I31-J31-K31 -> 13.22 | M31: 13
B32: 05 | C32: Nassim | E32: =IF(AND(VALUE(B32)<100, D32>0),D32*0.5,D32*0.25) -> 0 | F32: =IF(P32="C",Q32,IF(AND(VALUE(B32)<100, D32>0),12,IF(D32>0,2,0))) -> 0 | L32: =(E32+F32+G32+H32)-I32-J32-K32 -> 0 | Q32: 6
B33: 02 | C33: Sayed | E33: =IF(AND(VALUE(B33)<100, D33>0),D33*0.5,D33*0.25) -> 0 | F33: =IF(P33="C",Q33,IF(AND(VALUE(B33)<100, D33>0),12,IF(D33>0,2,0))) -> 0 | L33: =(E33+F33+G33+H33)-I33-J33-K33 -> 0 | Q33: 6
B34: 96 | C34: Rabah | D34: 312 | E34: =IF(AND(VALUE(B34)<100, D34>0),D34*0.5,D34*0.25) -> 156 | F34: =IF(P34="C",Q34,IF(AND(VALUE(B34)<100, D34>0),12,IF(D34>0,2,0))) -> 12 | G34: 5.5 | H34: 1.5 | I34: 123.88 | J34: 75 | K34: 0 | L34: =(E34+F34+G34+H34)-I34-J34-K34 -> -23.88 | M34: -24
B35: 33 | C35: Rachid | D35: 319 | E35: =IF(AND(VALUE(B35)<100, D35>0),D35*0.5,D35*0.25) -> 159.5 | F35: =IF(P35="C",Q35,IF(AND(VALUE(B35)<100, D35>0),12,IF(D35>0,2,0))) -> 12 | G35: 2.75 | H35: 0 | I35: 270.67 | J35: 17 | K35: 0 | L35: =(E35+F35+G35+H35)-I35-J35-K35 -> -113.42 | M35: -113
B36: 510 | C36: Samuel 510 | D36: 159 | E36: =IF(AND(VALUE(B36)<100, D36>0),D36*0.5,D36*0.25) -> 39.75 | F36: =IF(P36="C",Q36,IF(AND(VALUE(B36)<100, D36>0),12,IF(D36>0,2,0))) -> 2 | G36: 2.75 | H36: 0.75 | I36: 44.41 | J36: 0 | K36: 0 | L36: =(E36+F36+G36+H36)-I36-J36-K36 -> 0.84 | M36: 1
B37: 132 | C37: Samir 132 | E37: =IF(AND(VALUE(B37)<100, D37>0),D37*0.5,D37*0.25) -> 0 | F37: =IF(P37="C",Q37,IF(AND(VALUE(B37)<100, D37>0),12,IF(D37>0,2,0))) -> 0 | L37: =(E37+F37+G37+H37)-I37-J37-K37 -> 0 | P37: c
B38: 137 | C38: Osama 137 | E38: =IF(AND(VALUE(B38)<100, D38>0),D38*0.5,D38*0.25) -> 0 | F38: =IF(P38="C",Q38,IF(AND(VALUE(B38)<100, D38>0),12,IF(D38>0,2,0))) -> 0 | L38: =(E38+F38+G38+H38)-I38-J38-K38 -> 0 | Q38: 6
B39: 77 | C39: Shalaby | D39: 333 | E39: =IF(AND(VALUE(B39)<100, D39>0),D39*0.5,D39*0.25) -> 166.5 | F39: =IF(P39="C",Q39,IF(AND(VALUE(B39)<100, D39>0),12,IF(D39>0,2,0))) -> 12 | G39: 2.75 | H39: 7.75 | I39: 126.8 | J39: 47.5 | K39: 0 | L39: =(E39+F39+G39+H39)-I39-J39-K39 -> 14.7 | M39: 15 | Q39: 6
B40: 18 | C40: Spike | D40: 266 | E40: =IF(AND(VALUE(B40)<100, D40>0),D40*0.5,D40*0.25) -> 133 | F40: =IF(P40="C",Q40,IF(AND(VALUE(B40)<100, D40>0),12,IF(D40>0,2,0))) -> 12 | G40: 2.75 | H40: 4.25 | I40: 0 | J40: 23.6 | K40: 17 | L40: =(E40+F40+G40+H40)-I40-J40-K40 -> 111.4 | M40: 111
B41: 169 | C41: Tariq 169 | E41: =IF(AND(VALUE(B41)<100, D41>0),D41*0.5,D41*0.25) -> 0 | F41: =IF(P41="C",Q41,IF(AND(VALUE(B41)<100, D41>0),12,IF(D41>0,2,0))) -> 0 | L41: =(E41+F41+G41+H41)-I41-J41-K41 -> 0
...

Sheet Tues PM
A1: Date | B1: ='Mon AM'!B1+1 -> 46119 | D1: Shift | E1: PM
B3: Car | C3: Driver | D3: Book | E3: Comm | F3: Radio | G3: NYC CF | H3: PA Fee | I3: CC | J3: DB | K3: Misc | L3: NTD | M3: Cash in/out | N3: Driver Short | O3: Notes
B4: 138 | C4: Akram 138 | E4: =IF(AND(VALUE(B4)<100, D4>0),D4*0.5,D4*0.25) -> 0 | F4: =IF(P4="C",Q4,IF(AND(VALUE(B4)<100, D4>0),12,IF(D4>0,2,0))) -> 0 | L4: =(E4+F4+G4+H4)-I4-J4-K4 -> 0 | P4: c | Q4: 0 | R4: Total Book | S4: =D48 -> 2872
B5: 667 | C5: Abid 667 | E5: =IF(AND(VALUE(B5)<100, D5>0),D5*0.5,D5*0.25) -> 0 | F5: =IF(P5="C",Q5,IF(AND(VALUE(B5)<100, D5>0),12,IF(D5>0,2,0))) -> 0 | L5: =(E5+F5+G5+H5)-I5-J5-K5 -> 0 | Q5: 0 | R5: Comp Comm | S5: =E48 -> 1329.5
B6: 11 | C6: Alhassan | D6: 118 | E6: =IF(AND(VALUE(B6)<100, D6>0),D6*0.5,D6*0.25) -> 59 | F6: =IF(P6="C",Q6,IF(AND(VALUE(B6)<100, D6>0),12,IF(D6>0,2,0))) -> 6 | G6: 0 | H6: 7 | I6: 75.5 | J6: 0 | K6: 0 | L6: =(E6+F6+G6+H6)-I6-J6-K6 -> -3.5 | M6: -3 | P6: c | Q6: 6 | R6: Radio | S6: =F48 -> 116
B7: 70 | C7: Fahed | E7: =IF(AND(VALUE(B7)<100, D7>0),D7*0.5,D7*0.25) -> 0 | F7: =IF(P7="C",Q7,IF(AND(VALUE(B7)<100, D7>0),12,IF(D7>0,2,0))) -> 0 | L7: =(E7+F7+G7+H7)-I7-J7-K7 -> 0 | P7: c | Q7: 0 | R7: NYC CF | S7: =G48 -> 13.75
B8: 210 | C8: Boumadian | D8: 62 | E8: =IF(AND(VALUE(B8)<100, D8>0),D8*0.5,D8*0.25) -> 15.5 | F8: =IF(P8="C",Q8,IF(AND(VALUE(B8)<100, D8>0),12,IF(D8>0,2,0))) -> 2 | G8: 0 | H8: 0 | I8: 11 | J8: 0 | K8: 0 | L8: =(E8+F8+G8+H8)-I8-J8-K8 -> 6.5 | M8: 4 | N8: 2 | Q8: 6 | R8: PA Fee | S8: =H48 -> 65.25
B9: 012 | C9: Hamed | D9: 134 | E9: =IF(AND(VALUE(B9)<100, D9>0),D9*0.5,D9*0.25) -> 67 | F9: =IF(P9="C",Q9,IF(AND(VALUE(B9)<100, D9>0),12,IF(D9>0,2,0))) -> 0 | G9: 2.75 | H9: 4.25 | I9: 0 | J9: 50.96 | K9: 0 | L9: =(E9+F9+G9+H9)-I9-J9-K9 -> 23.04 | M9: 7 | N9: 16 | P9: c | Q9: 0 | R9: CC | S9: =I48 -> 1137.23
B10: 44 | C10: Cono | E10: =IF(AND(VALUE(B10)<100, D10>0),D10*0.5,D10*0.25) -> 0 | F10: =IF(P10="C",Q10,IF(AND(VALUE(B10)<100, D10>0),12,IF(D10>0,2,0))) -> 0 | L10: =(E10+F10+G10+H10)-I10-J10-K10 -> 0 | Q10: 6 | R10: DB | S10: =J48 -> 475.78
B11: 15 | C11: Hamdy | D11: 216 | E11: =IF(AND(VALUE(B11)<100, D11>0),D11*0.5,D11*0.25) -> 108 | F11: =IF(P11="C",Q11,IF(AND(VALUE(B11)<100, D11>0),12,IF(D11>0,2,0))) -> 12 | G11: 0 | H11: 0 | I11: 137 | J11: 32.2 | K11: 0 | L11: =(E11+F11+G11+H11)-I11-J11-K11 -> -49.2 | M11: -49 | N11: -49 | O11: Deducted $49 for 4/6 & 4/8 | Q11: 6 | R11: Misc | S11: =K48 -> 0
B12: 95 | C12: Divakar | D12: 182 | E12: =IF(AND(VALUE(B12)<100, D12>0),D12*0.5,D12*0.25) -> 91 | F12: =IF(P12="C",Q12,IF(AND(VALUE(B12)<100, D12>0),12,IF(D12>0,2,0))) -> 12 | G12: 2.75 | H12: 0.75 | I12: 6 | J12: 34.5 | K12: 0 | L12: =(E12+F12+G12+H12)-I12-J12-K12 -> 66 | M12: 66 | Q12: 6 | R12: Driver Short | S12: =N48 -> -23
B13: 012 | C13: Hosari | D13: 317 | E13: =IF(AND(VALUE(B13)<100, D13>0),D13*0.5,D13*0.25) -> 158.5 | F13: =IF(P13="C",Q13,IF(AND(VALUE(B13)<100, D13>0),12,IF(D13>0,2,0))) -> 12 | G13: 0 | H13: 7 | I13: 153.5 | J13: 97.75 | K13: 0 | L13: =(E13+F13+G13+H13)-I13-J13-K13 -> -73.75 | M13: -74 | Q13: 0 | S13: =S5+S6+S7-S9-S10-S11-S12 -> -130.76
B14: 02 | C14: Hassan | E14: =IF(AND(VALUE(B14)<100, D14>0),D14*0.5,D14*0.25) -> 0 | F14: =IF(P14="C",Q14,IF(AND(VALUE(B14)<100, D14>0),12,IF(D14>0,2,0))) -> 0 | L14: =(E14+F14+G14+H14)-I14-J14-K14 -> 0 | Q14: 6 | R14: Cash | S14: =M48 -> -121
B15: 11 | C15: John Meza | E15: =IF(AND(VALUE(B15)<100, D15>0),D15*0.5,D15*0.25) -> 0 | F15: =IF(P15="C",Q15,IF(AND(VALUE(B15)<100, D15>0),12,IF(D15>0,2,0))) -> 0 | L15: =(E15+F15+G15+H15)-I15-J15-K15 -> 0
B16: 99 | C16: Johnny 120 | D16: 122 | E16: =IF(AND(VALUE(B16)<100, D16>0),D16*0.5,D16*0.25) -> 61 | F16: =IF(P16="C",Q16,IF(AND(VALUE(B16)<100, D16>0),12,IF(D16>0,2,0))) -> 6 | G16: 0 | H16: 0 | I16: 33 | J16: 0 | K16: 0 | L16: =(E16+F16+G16+H16)-I16-J16-K16 -> 34 | M16: 34 | P16: c | Q16: 6
B17: 345 | C17: Abood 345 | E17: =IF(AND(VALUE(B17)<100, D17>0),D17*0.5,D17*0.25) -> 0 | F17: =IF(P17="C",Q17,IF(AND(VALUE(B17)<100, D17>0),12,IF(D17>0,2,0))) -> 0 | L17: =(E17+F17+G17+H17)-I17-J17-K17 -> 0
B18: 98 | C18: Maroc | E18: =IF(AND(VALUE(B18)<100, D18>0),D18*0.5,D18*0.25) -> 0 | F18: =IF(P18="C",Q18,IF(AND(VALUE(B18)<100, D18>0),12,IF(D18>0,2,0))) -> 0 | L18: =(E18+F18+G18+H18)-I18-J18-K18 -> 0 | R18: House Cars | S18: {=SUMPRODUCT((VALUE(B4:B47)<100)*(D4:D47>0))} -> 11
B19: 18 | C19: Mourad | E19: =IF(AND(VALUE(B19)<100, D19>0),D19*0.5,D19*0.25) -> 0 | F19: =IF(P19="C",Q19,IF(AND(VALUE(B19)<100, D19>0),12,IF(D19>0,2,0))) -> 0 | L19: =(E19+F19+G19+H19)-I19-J19-K19 -> 0 | Q19: 6 | R19: Private Cars | S19: {=SUMPRODUCT((VALUE(B4:B47)>100)*(D4:D47>0))} -> 4
B20: 06 | C20: Peter | D20: 272 | E20: =IF(AND(VALUE(B20)<100, D20>0),D20*0.5,D20*0.25) -> 136 | F20: =IF(P20="C",Q20,IF(AND(VALUE(B20)<100, D20>0),12,IF(D20>0,2,0))) -> 12 | G20: 2.75 | H20: 3.5 | I20: 111 | J20: 171.21 | K20: 0 | L20: =(E20+F20+G20+H20)-I20-J20-K20 -> -127.96 | M20: -128 | R20: Total | S20: =S18+S19 -> 15
B21: 01 | C21: Smail | D21: 329 | E21: =IF(AND(VALUE(B21)<100, D21>0),D21*0.5,D21*0.25) -> 164.5 | F21: =IF(P21="C",Q21,IF(AND(VALUE(B21)<100, D21>0),12,IF(D21>0,2,0))) -> 12 | G21: 0 | H21: 17.5 | I21: 267 | J21: 0 | K21: 0 | L21: =(E21+F21+G21+H21)-I21-J21-K21 -> -73 | M21: -73 | N21: -2 | O21: Deducted $2 for 4/10 | Q21: 6
B22: 445 | C22: Sadiki 445 | D22: 75 | E22: =IF(AND(VALUE(B22)<100, D22>0),D22*0.5,D22*0.25) -> 18.75 | F22: =IF(P22="C",Q22,IF(AND(VALUE(B22)<100, D22>0),12,IF(D22>0,2,0))) -> 2 | G22: 0 | H22: 0 | I22: 64 | J22: 0 | K22: 0 | L22: =(E22+F22+G22+H22)-I22-J22-K22 -> -43.25 | M22: -43 | N22: -5 | O22: Deducted $5 for 4/9
B23: 05 | C23: Soufiane | D23: 181 | E23: =IF(AND(VALUE(B23)<100, D23>0),D23*0.5,D23*0.25) -> 90.5 | F23: =IF(P23="C",Q23,IF(AND(VALUE(B23)<100, D23>0),12,IF(D23>0,2,0))) -> 12 | G23: 0 | H23: 3.5 | I23: 0 | J23: 0 | K23: 0 | L23: =(E23+F23+G23+H23)-I23-J23-K23 -> 106 | M23: 106 | Q23: 6
B24: 012 | C24: Reda | E24: =IF(AND(VALUE(B24)<100, D24>0),D24*0.5,D24*0.25) -> 0 | F24: =IF(P24="C",Q24,IF(AND(VALUE(B24)<100, D24>0),12,IF(D24>0,2,0))) -> 0 | L24: =(E24+F24+G24+H24)-I24-J24-K24 -> 0 | Q24: 0
B25: 33 | C25: Zaki | D25: 279 | E25: =IF(AND(VALUE(B25)<100, D25>0),D25*0.5,D25*0.25) -> 139.5 | F25: =IF(P25="C",Q25,IF(AND(VALUE(B25)<100, D25>0),12,IF(D25>0,2,0))) -> 12 | G25: 2.75 | H25: 3.5 | I25: 183.13 | J25: 23 | K25: 0 | L25: =(E25+F25+G25+H25)-I25-J25-K25 -> -48.38 | M25: -48 | Q25: 0
B26: 662 | C26: Aly 662 | E26: =IF(AND(VALUE(B26)<100, D26>0),D26*0.5,D26*0.25) -> 0 | F26: =IF(P26="C",Q26,IF(AND(VALUE(B26)<100, D26>0),12,IF(D26>0,2,0))) -> 0 | L26: =(E26+F26+G26+H26)-I26-J26-K26 -> 0 | Q26: 6
B27: 277 | C27: Nasser 277 | D27: 96 | E27: =IF(AND(VALUE(B27)<100, D27>0),D27*0.5,D27*0.25) -> 24 | F27: =IF(P27="C",Q27,IF(AND(VALUE(B27)<100, D27>0),12,IF(D27>0,2,0))) -> 2 | G27: 0 | H27: 0 | I27: 11 | J27: 0 | K27: 0 | L27: =(E27+F27+G27+H27)-I27-J27-K27 -> 15 | M27: 0 | N27: 15
B28: 96 | C28: Sayah | D28: 296 | E28: =IF(AND(VALUE(B28)<100, D28>0),D28*0.5,D28*0.25) -> 148 | F28: =IF(P28="C",Q28,IF(AND(VALUE(B28)<100, D28>0),12,IF(D28>0,2,0))) -> 12 | G28: 2.75 | H28: 18.25 | I28: 63.5 | J28: 66.16 | K28: 0 | L28: =(E28+F28+G28+H28)-I28-J28-K28 -> 51.34 | M28: 51 | Q28: 0 | T28: 1
B29: 395 | C29: Alibrahim 395 | E29: =IF(AND(VALUE(B29)<100, D29>0),D29*0.5,D29*0.25) -> 0 | F29: =IF(P29="C",Q29,IF(AND(VALUE(B29)<100, D29>0),12,IF(D29>0,2,0))) -> 0 | L29: =(E29+F29+G29+H29)-I29-J29-K29 -> 0 | T29: 0
B30: 77 | C30: Shousha | E30: =IF(AND(VALUE(B30)<100, D30>0),D30*0.5,D30*0.25) -> 0 | F30: =IF(P30="C",Q30,IF(AND(VALUE(B30)<100, D30>0),12,IF(D30>0,2,0))) -> 0 | L30: =(E30+F30+G30+H30)-I30-J30-K30 -> 0 | P30: c
B31: 96 | C31: Mahmoud | E31: =IF(AND(VALUE(B31)<100, D31>0),D31*0.5,D31*0.25) -> 0 | F31: =IF(P31="C",Q31,IF(AND(VALUE(B31)<100, D31>0),12,IF(D31>0,2,0))) -> 0 | L31: =(E31+F31+G31+H31)-I31-J31-K31 -> 0
B32: 610 | C32: Rizwan 610 | E32: =IF(AND(VALUE(B32)<100, D32>0),D32*0.5,D32*0.25) -> 0 | F32: =IF(P32="C",Q32,IF(AND(VALUE(B32)<100, D32>0),12,IF(D32>0,2,0))) -> 0 | L32: =(E32+F32+G32+H32)-I32-J32-K32 -> 0
B33: 158 | C33: Khamis 158 | E33: =IF(AND(VALUE(B33)<100, D33>0),D33*0.5,D33*0.25) -> 0 | F33: =IF(P33="C",Q33,IF(AND(VALUE(B33)<100, D33>0),12,IF(D33>0,2,0))) -> 0 | L33: =(E33+F33+G33+H33)-I33-J33-K33 -> 0
B34: 326 | C34: Obaydou 326 | E34: =IF(AND(VALUE(B34)<100, D34>0),D34*0.5,D34*0.25) -> 0 | F34: =IF(P34="C",Q34,IF(AND(VALUE(B34)<100, D34>0),12,IF(D34>0,2,0))) -> 0 | L34: =(E34+F34+G34+H34)-I34-J34-K34 -> 0
B35: 434 | C35: Radwan 434 | D35: 193 | E35: =IF(AND(VALUE(B35)<100, D35>0),D35*0.5,D35*0.25) -> 48.25 | F35: =IF(P35="C",Q35,IF(AND(VALUE(B35)<100, D35>0),12,IF(D35>0,2,0))) -> 2 | G35: 0 | H35: 0 | I35: 21.6 | J35: 0 | K35: 0 | L35: =(E35+F35+G35+H35)-I35-J35-K35 -> 28.65 | M35: 29
B36: 7 | C36: Rushdi | E36: =IF(AND(VALUE(B36)<100, D36>0),D36*0.5,D36*0.25) -> 0 | F36: =IF(P36="C",Q36,IF(AND(VALUE(B36)<100, D36>0),12,IF(D36>0,2,0))) -> 0 | L36: =(E36+F36+G36+H36)-I36-J36-K36 -> 0
E37: =IF(AND(VALUE(B37)<100, D37>0),D37*0.5,D37*0.25) -> 0 | F37: =IF(P37="C",Q37,IF(AND(VALUE(B37)<100, D37>0),12,IF(D37>0,2,0))) -> 0 | L37: =(E37+F37+G37+H37)-I37-J37-K37 -> 0
E38: =IF(AND(VALUE(B38)<100, D38>0),D38*0.5,D38*0.25) -> 0 | F38: =IF(P38="C",Q38,IF(AND(VALUE(B38)<100, D38>0),12,IF(D38>0,2,0))) -> 0 | L38: =(E38+F38+G38+H38)-I38-J38-K38 -> 0
E39: =IF(AND(VALUE(B39)<100, D39>0),D39*0.5,D39*0.25) -> 0 | F39: =IF(P39="C",Q39,IF(AND(VALUE(B39)<100, D39>0),12,IF(D39>0,2,0))) -> 0 | L39: =(E39+F39+G39+H39)-I39-J39-K39 -> 0
E40: =IF(AND(VALUE(B40)<100, D40>0),D40*0.5,D40*0.25) -> 0 | F40: =IF(P40="C",Q40,IF(AND(VALUE(B40)<100, D40>0),12,IF(D40>0,2,0))) -> 0 | L40: =(E40+F40+G40+H40)-I40-J40-K40 -> 0
E41: =IF(AND(VALUE(B41)<100, D41>0),D41*0.5,D41*0.25) -> 0 | F41: =IF(P41="C",Q41,IF(AND(VALUE(B41)<100, D41>0),12,IF(D41>0,2,0))) -> 0 | L41: =(E41+F41+G41+H41)-I41-J41-K41 -> 0
...

Sheet Wed AM
A1: Date | B1: ='Mon AM'!B1+2 -> 46120 | D1: Shift | E1: AM
B3: Car | C3: Driver | D3: Book | E3: Comm | F3: Radio | G3: NYC CF | H3: PA Fee | I3: CC | J3: DB | K3: Misc | L3: NTD | M3: Cash in/out | N3: Driver Short | O3: Notes
B4: 70 | C4: Alan C | D4: 267 | E4: =IF(AND(VALUE(B4)<100, D4>0),D4*0.5,D4*0.25) -> 133.5 | F4: =IF(P4="C",Q4,IF(AND(VALUE(B4)<100, D4>0),12,IF(D4>0,2,0))) -> 12 | G4: 2.75 | H4: 4.25 | I4: 0 | J4: 76.96 | K4: 0 | L4: =(E4+F4+G4+H4)-I4-J4-K4 -> 75.54 | M4: 76 | N4: 0 | Q4: 6 | R4: Total Book | S4: =D48 -> 6991
B5: 20 | C5: Hammad 125 | D5: 392 | E5: =IF(AND(VALUE(B5)<100, D5>0),D5*0.5,D5*0.25) -> 196 | F5: =IF(P5="C",Q5,IF(AND(VALUE(B5)<100, D5>0),12,IF(D5>0,2,0))) -> 12 | G5: 0 | H5: 10.5 | I5: 151 | J5: 11.5 | K5: 0 | L5: =(E5+F5+G5+H5)-I5-J5-K5 -> 56 | M5: 56 | N5: 0 | R5: Comp Comm | S5: =E48 -> 3143
B6: 114 | C6: Ash 114 | D6: 73 | E6: =IF(AND(VALUE(B6)<100, D6>0),D6*0.5,D6*0.25) -> 18.25 | F6: =IF(P6="C",Q6,IF(AND(VALUE(B6)<100, D6>0),12,IF(D6>0,2,0))) -> 2 | G6: 0 | H6: 0 | I6: 21 | J6: 0 | K6: 0 | L6: =(E6+F6+G6+H6)-I6-J6-K6 -> -0.75 | M6: -1 | Q6: 6 | R6: Radio | S6: =F48 -> 256
B7: 326 | C7: Obaydou 326 | D7: 249 | E7: =IF(AND(VALUE(B7)<100, D7>0),D7*0.5,D7*0.25) -> 62.25 | F7: =IF(P7="C",Q7,IF(AND(VALUE(B7)<100, D7>0),12,IF(D7>0,2,0))) -> 2 | G7: 5.5 | H7: 7.75 | I7: 139.46 | J7: 0 | K7: 0 | L7: =(E7+F7+G7+H7)-I7-J7-K7 -> -61.96 | M7: -62 | Q7: 6 | R7: NYC CF | S7: =G48 -> 71.5
B8: 33 | C8: Adnan | D8: 310 | E8: =IF(AND(VALUE(B8)<100, D8>0),D8*0.5,D8*0.25) -> 155 | F8: =IF(P8="C",Q8,IF(AND(VALUE(B8)<100, D8>0),12,IF(D8>0,2,0))) -> 12 | G8: 0 | H8: 10.5 | I8: 105.5 | J8: 0 | K8: 0 | L8: =(E8+F8+G8+H8)-I8-J8-K8 -> 72 | M8: 72 | Q8: 6 | R8: PA Fee | S8: =H48 -> 116.5
B9: 155 | C9: Abed 155 | E9: =IF(AND(VALUE(B9)<100, D9>0),D9*0.5,D9*0.25) -> 0 | F9: =IF(P9="C",Q9,IF(AND(VALUE(B9)<100, D9>0),12,IF(D9>0,2,0))) -> 0 | L9: =(E9+F9+G9+H9)-I9-J9-K9 -> 0 | Q9: 6 | R9: CC | S9: =I48 -> 2165.56
B10: 88 | C10: Alvis | D10: 254 | E10: =IF(AND(VALUE(B10)<100, D10>0),D10*0.5,D10*0.25) -> 127 | F10: =IF(P10="C",Q10,IF(AND(VALUE(B10)<100, D10>0),12,IF(D10>0,2,0))) -> 12 | G10: 0 | H10: 7 | I10: 63.5 | J10: 30 | K10: 0 | L10: =(E10+F10+G10+H10)-I10-J10-K10 -> 52.5 | M10: 52 | N10: 0 | R10: DB | S10: =J48 -> 1470.84
B11: 133 | C11: Bobby 133 | D11: 175 | E11: =IF(AND(VALUE(B11)<100, D11>0),D11*0.5,D11*0.25) -> 43.75 | F11: =IF(P11="C",Q11,IF(AND(VALUE(B11)<100, D11>0),12,IF(D11>0,2,0))) -> 2 | G11: 2.75 | H11: 4.25 | I11: 16 | J11: 69.05 | K11: 0 | L11: =(E11+F11+G11+H11)-I11-J11-K11 -> -32.3 | M11: -32 | R11: Misc | S11: =K48 -> 0
B12: 176 | C12: Djilali 176 | D12: 184 | E12: =IF(AND(VALUE(B12)<100, D12>0),D12*0.5,D12*0.25) -> 46 | F12: =IF(P12="C",Q12,IF(AND(VALUE(B12)<100, D12>0),12,IF(D12>0,2,0))) -> 2 | G12: 0 | H12: 7 | I12: 38 | J12: 0 | K12: 0 | L12: =(E12+F12+G12+H12)-I12-J12-K12 -> 17 | M12: 17 | Q12: 6 | R12: Driver Short | S12: =N48 -> 0
B13: 454 | C13: Agha 454 | D13: 119 | E13: =IF(AND(VALUE(B13)<100, D13>0),D13*0.5,D13*0.25) -> 29.75 | F13: =IF(P13="C",Q13,IF(AND(VALUE(B13)<100, D13>0),12,IF(D13>0,2,0))) -> 2 | G13: 0 | H13: 0 | I13: 13 | J13: 28.75 | K13: 0 | L13: =(E13+F13+G13+H13)-I13-J13-K13 -> -10 | M13: -10 | Q13: 6 | S13: =S5+S6+S7-S9-S10-S11-S12 -> -165.9
B14: 88 | C14: Ayad | D14: 229 | E14: =IF(AND(VALUE(B14)<100, D14>0),D14*0.5,D14*0.25) -> 114.5 | F14: =IF(P14="C",Q14,IF(AND(VALUE(B14)<100, D14>0),12,IF(D14>0,2,0))) -> 12 | G14: 11 | H14: 0.75 | I14: 132.82 | J14: 88.26 | K14: 0 | L14: =(E14+F14+G14+H14)-I14-J14-K14 -> -82.83 | M14: -83 | Q14: 6 | R14: Cash | S14: =M48 -> -49
B15: 96 | C15: Esmail | D15: 195 | E15: =IF(AND(VALUE(B15)<100, D15>0),D15*0.5,D15*0.25) -> 97.5 | F15: =IF(P15="C",Q15,IF(AND(VALUE(B15)<100, D15>0),12,IF(D15>0,2,0))) -> 12 | G15: 0 | H15: 7 | I15: 80.5 | J15: 0 | K15: 0 | L15: =(E15+F15+G15+H15)-I15-J15-K15 -> 36 | M15: 36
B16: 26 | C16: Gus | D16: 282 | E16: =IF(AND(VALUE(B16)<100, D16>0),D16*0.5,D16*0.25) -> 141 | F16: =IF(P16="C",Q16,IF(AND(VALUE(B16)<100, D16>0),12,IF(D16>0,2,0))) -> 12 | G16: 5.5 | H16: 5 | I16: 0 | J16: 32.8 | K16: 0 | L16: =(E16+F16+G16+H16)-I16-J16-K16 -> 130.7 | M16: 131 | Q16: 0
B17: 11 | C17: Hashem | E17: =IF(AND(VALUE(B17)<100, D17>0),D17*0.5,D17*0.25) -> 0 | F17: =IF(P17="C",Q17,IF(AND(VALUE(B17)<100, D17>0),12,IF(D17>0,2,0))) -> 0 | L17: =(E17+F17+G17+H17)-I17-J17-K17 -> 0 | Q17: 6
B18: 27 | C18: Hassan | E18: =IF(AND(VALUE(B18)<100, D18>0),D18*0.5,D18*0.25) -> 0 | F18: =IF(P18="C",Q18,IF(AND(VALUE(B18)<100, D18>0),12,IF(D18>0,2,0))) -> 0 | L18: =(E18+F18+G18+H18)-I18-J18-K18 -> 0 | Q18: 6 | R18: House Cars | S18: {=SUMPRODUCT((VALUE(B4:B47)<100)*(D4:D47>0))} -> 20
B19: 33 | C19: Ihab | E19: =IF(AND(VALUE(B19)<100, D19>0),D19*0.5,D19*0.25) -> 0 | F19: =IF(P19="C",Q19,IF(AND(VALUE(B19)<100, D19>0),12,IF(D19>0,2,0))) -> 0 | L19: =(E19+F19+G19+H19)-I19-J19-K19 -> 0 | Q19: 6 | R19: Private Cars | S19: {=SUMPRODUCT((VALUE(B4:B47)>100)*(D4:D47>0))} -> 8
B20: 77 | C20: Nofal | D20: 163 | E20: =IF(AND(VALUE(B20)<100, D20>0),D20*0.5,D20*0.25) -> 81.5 | F20: =IF(P20="C",Q20,IF(AND(VALUE(B20)<100, D20>0),12,IF(D20>0,2,0))) -> 12 | G20: 5.5 | H20: 1.5 | I20: 19 | J20: 107.56 | K20: 0 | L20: =(E20+F20+G20+H20)-I20-J20-K20 -> -26.06 | M20: -26 | Q20: 6 | R20: Total | S20: =S18+S19 -> 28
B21: 88 | C21: Ibrahim | E21: =IF(AND(VALUE(B21)<100, D21>0),D21*0.5,D21*0.25) -> 0 | F21: =IF(P21="C",Q21,IF(AND(VALUE(B21)<100, D21>0),12,IF(D21>0,2,0))) -> 0 | L21: =(E21+F21+G21+H21)-I21-J21-K21 -> 0 | Q21: 5
B22: 27 | C22: Kim | D22: 175 | E22: =IF(AND(VALUE(B22)<100, D22>0),D22*0.5,D22*0.25) -> 87.5 | F22: =IF(P22="C",Q22,IF(AND(VALUE(B22)<100, D22>0),12,IF(D22>0,2,0))) -> 12 | G22: 0 | H22: 0 | I22: 12 | J22: 54.65 | K22: 0 | L22: =(E22+F22+G22+H22)-I22-J22-K22 -> 32.85 | M22: 33 | Q22: 6
B23: 622 | C23: Joseph 622 | D23: 240 | E23: =IF(AND(VALUE(B23)<100, D23>0),D23*0.5,D23*0.25) -> 60 | F23: =IF(P23="C",Q23,IF(AND(VALUE(B23)<100, D23>0),12,IF(D23>0,2,0))) -> 2 | G23: 0 | H23: 10.5 | I23: 170.5 | J23: 25.4 | K23: 0 | L23: =(E23+F23+G23+H23)-I23-J23-K23 -> -123.4 | M23: -123 | Q23: 6
B24: 01 | C24: Kamal | D24: 738 | E24: =IF(AND(VALUE(B24)<100, D24>0),D24*0.5,D24*0.25) -> 369 | F24: =IF(P24="C",Q24,IF(AND(VALUE(B24)<100, D24>0),12,IF(D24>0,2,0))) -> 12 | G24: 5.5 | H24: 11.25 | I24: 218 | J24: 481.88 | K24: 0 | L24: =(E24+F24+G24+H24)-I24-J24-K24 -> -302.13 | M24: -302
B25: 55 | C25: Karlo | D25: 250 | E25: =IF(AND(VALUE(B25)<100, D25>0),D25*0.5,D25*0.25) -> 125 | F25: =IF(P25="C",Q25,IF(AND(VALUE(B25)<100, D25>0),12,IF(D25>0,2,0))) -> 12 | G25: 0 | H25: 0 | I25: 32 | J25: 9.2 | K25: 0 | L25: =(E25+F25+G25+H25)-I25-J25-K25 -> 95.8 | M25: 96 | Q25: 0
B26: 77 | C26: Hesham | E26: =IF(AND(VALUE(B26)<100, D26>0),D26*0.5,D26*0.25) -> 0 | F26: =IF(P26="C",Q26,IF(AND(VALUE(B26)<100, D26>0),12,IF(D26>0,2,0))) -> 0 | L26: =(E26+F26+G26+H26)-I26-J26-K26 -> 0 | Q26: 6
B27: 77 | C27: Khaled | D27: 292 | E27: =IF(AND(VALUE(B27)<100, D27>0),D27*0.5,D27*0.25) -> 146 | F27: =IF(P27="C",Q27,IF(AND(VALUE(B27)<100, D27>0),12,IF(D27>0,2,0))) -> 12 | G27: 5.5 | H27: 1.5 | I27: 75.96 | J27: 123.05 | K27: 0 | L27: =(E27+F27+G27+H27)-I27-J27-K27 -> -34.01 | M27: -34 | T27: 6
B28: 844 | C28: Khodr 844 | E28: =IF(AND(VALUE(B28)<100, D28>0),D28*0.5,D28*0.25) -> 0 | F28: =IF(P28="C",Q28,IF(AND(VALUE(B28)<100, D28>0),12,IF(D28>0,2,0))) -> 0 | L28: =(E28+F28+G28+H28)-I28-J28-K28 -> 0 | Q28: 6 | T28: 4
B29: 644 | C29: Muhiddin 644 | D29: 224 | E29: =IF(AND(VALUE(B29)<100, D29>0),D29*0.5,D29*0.25) -> 56 | F29: =IF(P29="C",Q29,IF(AND(VALUE(B29)<100, D29>0),12,IF(D29>0,2,0))) -> 2 | G29: 8.25 | H29: 1.5 | I29: 8.4 | J29: 63.86 | K29: 0 | L29: =(E29+F29+G29+H29)-I29-J29-K29 -> -4.51 | M29: -5 | Q29: 6
B30: 109 | C30: Nasser 109 | E30: =IF(AND(VALUE(B30)<100, D30>0),D30*0.5,D30*0.25) -> 0 | F30: =IF(P30="C",Q30,IF(AND(VALUE(B30)<100, D30>0),12,IF(D30>0,2,0))) -> 0 | L30: =(E30+F30+G30+H30)-I30-J30-K30 -> 0 | Q30: 0
B31: 25 | C31: Mustapha | D31: 260 | E31: =IF(AND(VALUE(B31)<100, D31>0),D31*0.5,D31*0.25) -> 130 | F31: =IF(P31="C",Q31,IF(AND(VALUE(B31)<100, D31>0),12,IF(D31>0,2,0))) -> 12 | G31: 2.75 | H31: 4.25 | I31: 156.42 | J31: 60.96 | K31: 0 | L31: =(E31+F31+G31+H31)-I31-J31-K31 -> -68.38 | M31: -68 | Q31: 0
B32: 05 | C32: Nassim | E32: =IF(AND(VALUE(B32)<100, D32>0),D32*0.5,D32*0.25) -> 0 | F32: =IF(P32="C",Q32,IF(AND(VALUE(B32)<100, D32>0),12,IF(D32>0,2,0))) -> 0 | L32: =(E32+F32+G32+H32)-I32-J32-K32 -> 0 | Q32: 6
B33: 02 | C33: Sayed | E33: =IF(AND(VALUE(B33)<100, D33>0),D33*0.5,D33*0.25) -> 0 | F33: =IF(P33="C",Q33,IF(AND(VALUE(B33)<100, D33>0),12,IF(D33>0,2,0))) -> 0 | L33: =(E33+F33+G33+H33)-I33-J33-K33 -> 0
B34: 96 | C34: Rabah | D34: 252 | E34: =IF(AND(VALUE(B34)<100, D34>0),D34*0.5,D34*0.25) -> 126 | F34: =IF(P34="C",Q34,IF(AND(VALUE(B34)<100, D34>0),12,IF(D34>0,2,0))) -> 12 | G34: 2.75 | H34: 0.75 | I34: 115.27 | J34: 0 | K34: 0 | L34: =(E34+F34+G34+H34)-I34-J34-K34 -> 26.23 | M34: 26
B35: 33 | C35: Rachid | D35: 202 | E35: =IF(AND(VALUE(B35)<100, D35>0),D35*0.5,D35*0.25) -> 101 | F35: =IF(P35="C",Q35,IF(AND(VALUE(B35)<100, D35>0),12,IF(D35>0,2,0))) -> 12 | G35: 0 | H35: 7 | I35: 138.6 | J35: 0 | K35: 0 | L35: =(E35+F35+G35+H35)-I35-J35-K35 -> -18.6 | M35: -19
B36: 510 | C36: Samuel 510 | D36: 146 | E36: =IF(AND(VALUE(B36)<100, D36>0),D36*0.5,D36*0.25) -> 36.5 | F36: =IF(P36="C",Q36,IF(AND(VALUE(B36)<100, D36>0),12,IF(D36>0,2,0))) -> 2 | G36: 0 | H36: 0 | I36: 24 | J36: 9.2 | K36: 0 | L36: =(E36+F36+G36+H36)-I36-J36-K36 -> 5.3 | M36: 5
B37: 132 | C37: Samir 132 | E37: =IF(AND(VALUE(B37)<100, D37>0),D37*0.5,D37*0.25) -> 0 | F37: =IF(P37="C",Q37,IF(AND(VALUE(B37)<100, D37>0),12,IF(D37>0,2,0))) -> 0 | L37: =(E37+F37+G37+H37)-I37-J37-K37 -> 0 | P37: c
B38: 137 | C38: Osama 137 | E38: =IF(AND(VALUE(B38)<100, D38>0),D38*0.5,D38*0.25) -> 0 | F38: =IF(P38="C",Q38,IF(AND(VALUE(B38)<100, D38>0),12,IF(D38>0,2,0))) -> 0 | L38: =(E38+F38+G38+H38)-I38-J38-K38 -> 0 | Q38: 6
B39: 77 | C39: Shalaby | D39: 308 | E39: =IF(AND(VALUE(B39)<100, D39>0),D39*0.5,D39*0.25) -> 154 | F39: =IF(P39="C",Q39,IF(AND(VALUE(B39)<100, D39>0),12,IF(D39>0,2,0))) -> 12 | G39: 5.5 | H39: 1.5 | I39: 179.36 | J39: 6 | K39: 0 | L39: =(E39+F39+G39+H39)-I39-J39-K39 -> -12.36 | M39: -12 | Q39: 6
B40: 18 | C40: Spike | D40: 258 | E40: =IF(AND(VALUE(B40)<100, D40>0),D40*0.5,D40*0.25) -> 129 | F40: =IF(P40="C",Q40,IF(AND(VALUE(B40)<100, D40>0),12,IF(D40>0,2,0))) -> 12 | G40: 2.75 | H40: 4.25 | I40: 19 | J40: 20.7 | K40: 0 | L40: =(E40+F40+G40+H40)-I40-J40-K40 -> 108.3 | M40: 108
B41: 169 | C41: Tariq 169 | E41: =IF(AND(VALUE(B41)<100, D41>0),D41*0.5,D41*0.25) -> 0 | F41: =IF(P41="C",Q41,IF(AND(VALUE(B41)<100, D41>0),12,IF(D41>0,2,0))) -> 0 | L41: =(E41+F41+G41+H41)-I41-J41-K41 -> 0
...

Sheet Wed PM
A1: Date | B1: ='Mon AM'!B1+2 -> 46120 | D1: Shift | E1: PM
B3: Car | C3: Driver | D3: Book | E3: Comm | F3: Radio | G3: NYC CF | H3: PA Fee | I3: CC | J3: DB | K3: Misc | L3: NTD | M3: Cash in/out | N3: Driver Short | O3: Notes
B4: 138 | C4: Akram 138 | E4: =IF(AND(VALUE(B4)<100, D4>0),D4*0.5,D4*0.25) -> 0 | F4: =IF(P4="C",Q4,IF(AND(VALUE(B4)<100, D4>0),12,IF(D4>0,2,0))) -> 0 | L4: =(E4+F4+G4+H4)-I4-J4-K4 -> 0 | P4: c | Q4: 0 | R4: Total Book | S4: =D48 -> 2731
B5: 667 | C5: Abid 667 | E5: =IF(AND(VALUE(B5)<100, D5>0),D5*0.5,D5*0.25) -> 0 | F5: =IF(P5="C",Q5,IF(AND(VALUE(B5)<100, D5>0),12,IF(D5>0,2,0))) -> 0 | L5: =(E5+F5+G5+H5)-I5-J5-K5 -> 0 | Q5: 6 | R5: Comp Comm | S5: =E48 -> 1258.5
B6: 11 | C6: Alhassan | E6: =IF(AND(VALUE(B6)<100, D6>0),D6*0.5,D6*0.25) -> 0 | F6: =IF(P6="C",Q6,IF(AND(VALUE(B6)<100, D6>0),12,IF(D6>0,2,0))) -> 0 | L6: =(E6+F6+G6+H6)-I6-J6-K6 -> 0 | Q6: 6 | R6: Radio | S6: =F48 -> 104
B7: 70 | C7: Adnan | E7: =IF(AND(VALUE(B7)<100, D7>0),D7*0.5,D7*0.25) -> 0 | F7: =IF(P7="C",Q7,IF(AND(VALUE(B7)<100, D7>0),12,IF(D7>0,2,0))) -> 0 | L7: =(E7+F7+G7+H7)-I7-J7-K7 -> 0 | Q7: 6 | R7: NYC CF | S7: =G48 -> 16.5
B8: 210 | C8: Boumadian | D8: 20 | E8: =IF(AND(VALUE(B8)<100, D8>0),D8*0.5,D8*0.25) -> 5 | F8: =IF(P8="C",Q8,IF(AND(VALUE(B8)<100, D8>0),12,IF(D8>0,2,0))) -> 2 | G8: 0 | H8: 0 | I8: 11 | J8: 0 | K8: 0 | L8: =(E8+F8+G8+H8)-I8-J8-K8 -> -4 | M8: -4 | N8: -4 | O8: Deducted $4 for 4/7 | Q8: 6 | R8: PA Fee | S8: =H48 -> 68.75
B9: 012 | C9: Hamed | E9: =IF(AND(VALUE(B9)<100, D9>0),D9*0.5,D9*0.25) -> 0 | F9: =IF(P9="C",Q9,IF(AND(VALUE(B9)<100, D9>0),12,IF(D9>0,2,0))) -> 0 | L9: =(E9+F9+G9+H9)-I9-J9-K9 -> 0 | Q9: 0 | R9: CC | S9: =I48 -> 1054.92
B10: 44 | C10: Cono | E10: =IF(AND(VALUE(B10)<100, D10>0),D10*0.5,D10*0.25) -> 0 | F10: =IF(P10="C",Q10,IF(AND(VALUE(B10)<100, D10>0),12,IF(D10>0,2,0))) -> 0 | L10: =(E10+F10+G10+H10)-I10-J10-K10 -> 0 | Q10: 6 | R10: DB | S10: =J48 -> 562.79
B11: 15 | C11: Hamdy | D11: 162 | E11: =IF(AND(VALUE(B11)<100, D11>0),D11*0.5,D11*0.25) -> 81 | F11: =IF(P11="C",Q11,IF(AND(VALUE(B11)<100, D11>0),12,IF(D11>0,2,0))) -> 12 | G11: 0 | H11: 0 | I11: 28.05 | J11: 0 | K11: 14 | L11: =(E11+F11+G11+H11)-I11-J11-K11 -> 50.95 | M11: 32 | N11: 19 | Q11: 6 | R11: Misc | S11: =K48 -> 14
B12: 02 | C12: Divakar | D12: 210 | E12: =IF(AND(VALUE(B12)<100, D12>0),D12*0.5,D12*0.25) -> 105 | F12: =IF(P12="C",Q12,IF(AND(VALUE(B12)<100, D12>0),12,IF(D12>0,2,0))) -> 12 | G12: 2.75 | H12: 3.5 | I12: 118.25 | J12: 13.8 | K12: 0 | L12: =(E12+F12+G12+H12)-I12-J12-K12 -> -8.8 | M12: -9 | Q12: 6 | R12: Driver Short | S12: =N48 -> 15
B13: 012 | C13: Hosari | D13: 346 | E13: =IF(AND(VALUE(B13)<100, D13>0),D13*0.5,D13*0.25) -> 173 | F13: =IF(P13="C",Q13,IF(AND(VALUE(B13)<100, D13>0),12,IF(D13>0,2,0))) -> 12 | G13: 2.75 | H13: 11.25 | I13: 217.16 | J13: 165.96 | K13: 0 | L13: =(E13+F13+G13+H13)-I13-J13-K13 -> -184.12 | M13: -184 | Q13: 0 | S13: =S5+S6+S7-S9-S10-S11-S12 -> -267.71
B14: 263 | C14: Tarek 263 | E14: =IF(AND(VALUE(B14)<100, D14>0),D14*0.5,D14*0.25) -> 0 | F14: =IF(P14="C",Q14,IF(AND(VALUE(B14)<100, D14>0),12,IF(D14>0,2,0))) -> 0 | L14: =(E14+F14+G14+H14)-I14-J14-K14 -> 0 | Q14: 6 | R14: Cash | S14: =M48 -> -202
B15: 11 | C15: John Meza | E15: =IF(AND(VALUE(B15)<100, D15>0),D15*0.5,D15*0.25) -> 0 | F15: =IF(P15="C",Q15,IF(AND(VALUE(B15)<100, D15>0),12,IF(D15>0,2,0))) -> 0 | L15: =(E15+F15+G15+H15)-I15-J15-K15 -> 0
B16: 15 | C16: Johnny 120 | D16: 191 | E16: =IF(AND(VALUE(B16)<100, D16>0),D16*0.5,D16*0.25) -> 95.5 | F16: =IF(P16="C",Q16,IF(AND(VALUE(B16)<100, D16>0),12,IF(D16>0,2,0))) -> 12 | G16: 0 | H16: 3.5 | I16: 10 | J16: 138 | K16: 0 | L16: =(E16+F16+G16+H16)-I16-J16-K16 -> -37 | M16: -37
B17: 02 | C17: Kuhali | E17: =IF(AND(VALUE(B17)<100, D17>0),D17*0.5,D17*0.25) -> 0 | F17: =IF(P17="C",Q17,IF(AND(VALUE(B17)<100, D17>0),12,IF(D17>0,2,0))) -> 0 | L17: =(E17+F17+G17+H17)-I17-J17-K17 -> 0 | Q17: 6
B18: 55 | C18: Maroc | E18: =IF(AND(VALUE(B18)<100, D18>0),D18*0.5,D18*0.25) -> 0 | F18: =IF(P18="C",Q18,IF(AND(VALUE(B18)<100, D18>0),12,IF(D18>0,2,0))) -> 0 | L18: =(E18+F18+G18+H18)-I18-J18-K18 -> 0 | Q18: 0 | R18: House Cars | S18: {=SUMPRODUCT((VALUE(B4:B47)<100)*(D4:D47>0))} -> 9
B19: 18 | C19: Mourad | E19: =IF(AND(VALUE(B19)<100, D19>0),D19*0.5,D19*0.25) -> 0 | F19: =IF(P19="C",Q19,IF(AND(VALUE(B19)<100, D19>0),12,IF(D19>0,2,0))) -> 0 | L19: =(E19+F19+G19+H19)-I19-J19-K19 -> 0 | P19: c | Q19: 0 | R19: Private Cars | S19: {=SUMPRODUCT((VALUE(B4:B47)>100)*(D4:D47>0))} -> 4
B20: 06 | C20: Peter | D20: 272 | E20: =IF(AND(VALUE(B20)<100, D20>0),D20*0.5,D20*0.25) -> 136 | F20: =IF(P20="C",Q20,IF(AND(VALUE(B20)<100, D20>0),12,IF(D20>0,2,0))) -> 12 | G20: 2.75 | H20: 7 | I20: 64.5 | J20: 144.33 | K20: 0 | L20: =(E20+F20+G20+H20)-I20-J20-K20 -> -51.08 | M20: -51 | R20: Total | S20: =S18+S19 -> 13
B21: 44 | C21: Madjid | E21: =IF(AND(VALUE(B21)<100, D21>0),D21*0.5,D21*0.25) -> 0 | F21: =IF(P21="C",Q21,IF(AND(VALUE(B21)<100, D21>0),12,IF(D21>0,2,0))) -> 0 | L21: =(E21+F21+G21+H21)-I21-J21-K21 -> 0 | Q21: 6
B22: 15 | C22: Smail | D22: 324 | E22: =IF(AND(VALUE(B22)<100, D22>0),D22*0.5,D22*0.25) -> 162 | F22: =IF(P22="C",Q22,IF(AND(VALUE(B22)<100, D22>0),12,IF(D22>0,2,0))) -> 12 | G22: 5.5 | H22: 11.25 | I22: 136.06 | J22: 62.75 | K22: 0 | L22: =(E22+F22+G22+H22)-I22-J22-K22 -> -8.06 | M22: -8 | Q22: 6
B23: 05 | C23: Soufiane | D23: 372 | E23: =IF(AND(VALUE(B23)<100, D23>0),D23*0.5,D23*0.25) -> 186 | F23: =IF(P23="C",Q23,IF(AND(VALUE(B23)<100, D23>0),12,IF(D23>0,2,0))) -> 12 | G23: 0 | H23: 10.5 | I23: 165.4 | J23: 0 | K23: 0 | L23: =(E23+F23+G23+H23)-I23-J23-K23 -> 43.1 | M23: 43 | Q23: 0
B24: 012 | C24: Tanios | E24: =IF(AND(VALUE(B24)<100, D24>0),D24*0.5,D24*0.25) -> 0 | F24: =IF(P24="C",Q24,IF(AND(VALUE(B24)<100, D24>0),12,IF(D24>0,2,0))) -> 0 | L24: =(E24+F24+G24+H24)-I24-J24-K24 -> 0 | Q24: 6
B25: 80 | C25: Zaki | D25: 286 | E25: =IF(AND(VALUE(B25)<100, D25>0),D25*0.5,D25*0.25) -> 143 | F25: =IF(P25="C",Q25,IF(AND(VALUE(B25)<100, D25>0),12,IF(D25>0,2,0))) -> 12 | G25: 2.75 | H25: 11.25 | I25: 109 | J25: 0 | K25: 0 | L25: =(E25+F25+G25+H25)-I25-J25-K25 -> 60 | M25: 60 | Q25: 6
B26: 15 | C26: Nofal | E26: =IF(AND(VALUE(B26)<100, D26>0),D26*0.5,D26*0.25) -> 0 | F26: =IF(P26="C",Q26,IF(AND(VALUE(B26)<100, D26>0),12,IF(D26>0,2,0))) -> 0 | L26: =(E26+F26+G26+H26)-I26-J26-K26 -> 0 | Q26: 6
B27: 44 | C27: Reda | E27: =IF(AND(VALUE(B27)<100, D27>0),D27*0.5,D27*0.25) -> 0 | F27: =IF(P27="C",Q27,IF(AND(VALUE(B27)<100, D27>0),12,IF(D27>0,2,0))) -> 0 | L27: =(E27+F27+G27+H27)-I27-J27-K27 -> 0
B28: 445 | C28: Sadiki 445 | D28: 74 | E28: =IF(AND(VALUE(B28)<100, D28>0),D28*0.5,D28*0.25) -> 18.5 | F28: =IF(P28="C",Q28,IF(AND(VALUE(B28)<100, D28>0),12,IF(D28>0,2,0))) -> 2 | G28: 0 | H28: 0 | I28: 0 | J28: 28.75 | K28: 0 | L28: =(E28+F28+G28+H28)-I28-J28-K28 -> -8.25 | M28: -8 | T28: 1
B29: 77 | C29: Shousha | E29: =IF(AND(VALUE(B29)<100, D29>0),D29*0.5,D29*0.25) -> 0 | F29: =IF(P29="C",Q29,IF(AND(VALUE(B29)<100, D29>0),12,IF(D29>0,2,0))) -> 0 | L29: =(E29+F29+G29+H29)-I29-J29-K29 -> 0 | T29: 1
B30: 95 | C30: Sayah | D30: 140 | E30: =IF(AND(VALUE(B30)<100, D30>0),D30*0.5,D30*0.25) -> 70 | F30: =IF(P30="C",Q30,IF(AND(VALUE(B30)<100, D30>0),12,IF(D30>0,2,0))) -> 0 | G30: 0 | H30: 7 | I30: 68.5 | J30: 0 | K30: 0 | L30: =(E30+F30+G30+H30)-I30-J30-K30 -> 8.5 | M30: 9 | P30: c | Q30: 0
B31: 277 | C31: Nasser 277 | E31: =IF(AND(VALUE(B31)<100, D31>0),D31*0.5,D31*0.25) -> 0 | F31: =IF(P31="C",Q31,IF(AND(VALUE(B31)<100, D31>0),12,IF(D31>0,2,0))) -> 0 | L31: =(E31+F31+G31+H31)-I31-J31-K31 -> 0
B32: 158 | C32: Khamis 158 | E32: =IF(AND(VALUE(B32)<100, D32>0),D32*0.5,D32*0.25) -> 0 | F32: =IF(P32="C",Q32,IF(AND(VALUE(B32)<100, D32>0),12,IF(D32>0,2,0))) -> 0 | L32: =(E32+F32+G32+H32)-I32-J32-K32 -> 0
B33: 434 | C33: Radwan 434 | D33: 224 | E33: =IF(AND(VALUE(B33)<100, D33>0),D33*0.5,D33*0.25) -> 56 | F33: =IF(P33="C",Q33,IF(AND(VALUE(B33)<100, D33>0),12,IF(D33>0,2,0))) -> 2 | G33: 0 | H33: 3.5 | I33: 83 | J33: 0 | K33: 0 | L33: =(E33+F33+G33+H33)-I33-J33-K33 -> -21.5 | M33: -21
B34: 662 | C34: Aly 662 | D34: 110 | E34: =IF(AND(VALUE(B34)<100, D34>0),D34*0.5,D34*0.25) -> 27.5 | F34: =IF(P34="C",Q34,IF(AND(VALUE(B34)<100, D34>0),12,IF(D34>0,2,0))) -> 2 | G34: 0 | H34: 0 | I34: 44 | J34: 9.2 | K34: 0 | L34: =(E34+F34+G34+H34)-I34-J34-K34 -> -23.7 | M34: -24
B35: 05 | C35: Rushdi | E35: =IF(AND(VALUE(B35)<100, D35>0),D35*0.5,D35*0.25) -> 0 | F35: =IF(P35="C",Q35,IF(AND(VALUE(B35)<100, D35>0),12,IF(D35>0,2,0))) -> 0 | L35: =(E35+F35+G35+H35)-I35-J35-K35 -> 0
